Workbook

Sheet Produktivitas
A1: Produktifitas (bcm/jam) | B1: Produktivitas Simulasi | D1: NO | E1: Alat Angkut | F1: Tgl | G1: Waktu (menit) | M1: Pengamatan | Q1: Produksi Aktual (bcm/jam) | S1: NO | T1: Alat Angkut | U1: Tgl | V1: Waktu (menit) | AB1: Pengamatan | AF1: Produksi Aktual (bcm/jam)
A2: 133.41176 | B2: =A2+A2*0.1 -> 146.75294 | G2: Manuver Kosong | H2: Pemuatan | I2: Angkut bermuatan | J2: Mengambil Posisi Untuk Penumpahan | K2: Dumping | L2: Kembali (Kosong) | M2: 1 | N2: 2 | O2: 3 | P2: Rata-Rata (menit) | V2: Manuver Kosong | W2: Pemuatan | X2: Angkut bermuatan | Y2: Mengambil Posisi Untuk Penumpahan | Z2: Dumping | AA2: Kembali (Kosong) | AB2: 1 | AC2: 2 | AD2: 3 | AE2: Rata-Rata (menit)
A3: 129.50749 | B3: =A3+A3*0.1 -> 142.45824
A4: 136.01199 | B4: =A4+A4*0.1 -> 149.61319 | D4: 4 | E4: ADT 416 | F4: 45699 | G4: 0.25 | H4: 2.14 | I4: 6 | J4: 0.2 | K4: 0.26 | L4: 4.56 | M4: =SUM(G4:L4) -> 13.41 | N4: =SUM(G5:L5) -> 13.74 | O4: =SUM(G6:L6) -> 13.65 | P4: =(M4+N4+O4)/3 -> 13.6 | Q4: =60/P4*45 -> 198.52941 | S4: 4 | T4: ADT 416 | U4: 45699 | V4: 0.25 | W4: 2.3 | X4: 6 | Y4: 0.22 | Z4: 0.3 | AA4: 5.5 | AB4: =SUM(V4:AA4) -> 14.57 | AC4: =SUM(V5:AA5) -> 15.17 | AD4: =SUM(V6:AA6) -> 15.21 | AE4: =(AB4+AC4+AD4)/3 -> 14.983333 | AF4: =60/AE4*45 -> 180.20022
A5: 134.20118 | B5: =A5+A5*0.1 -> 147.6213 | G5: 0.2 | H5: 2.16 | I5: 5.7 | J5: 0.25 | K5: 0.23 | L5: 5.2 | V5: 0.23 | W5: 2.34 | X5: 6 | Y5: 0.25 | Z5: 0.35 | AA5: 6
A6: 124.35915 | B6: =A6+A6*0.1 -> 136.79507 | G6: 0.18 | H6: 2.2 | I6: 5.6 | J6: 0.27 | K6: 0.3 | L6: 5.1 | V6: 0.25 | W6: 2.27 | X6: 6.2 | Y6: 0.34 | Z6: 0.35 | AA6: 5.8
A7: 135.40299 | B7: =A7+A7*0.1 -> 148.94328 | D7: 1 | E7: ADT 419 | F7: 45693 | G7: 0.15 | H7: 2.29 | I7: 6.22 | J7: 0.25 | K7: 0.3 | L7: 5.1 | M7: =SUM(G7:L7) -> 14.31 | N7: =SUM(G8:L8) -> 13.53 | O7: =SUM(G9:L9) -> 14.19 | P7: =(M7+N7+O7)/3 -> 14.01 | Q7: =60/P7*45 -> 192.71949 | S7: 1 | T7: ADT 419 | U7: 45693 | V7: 0.2 | W7: 2.4 | X7: 7 | Y7: 0.35 | Z7: 0.4 | AA7: 5.5 | AB7: =SUM(V7:AA7) -> 15.85 | AC7: =SUM(V8:AA8) -> 15.13 | AD7: =SUM(V9:AA9) -> 14.75 | AE7: =(AB7+AC7+AD7)/3 -> 15.243333 | AF7: =60/AE7*45 -> 177.12661
A8: 131.66909 | B8: =A8+A8*0.1 -> 144.83599 | G8: 0.16 | H8: 2.3 | I8: 5.44 | J8: 0.21 | K8: 0.2 | L8: 5.22 | V8: 0.2 | W8: 2.4 | X8: 6 | Y8: 0.25 | Z8: 0.28 | AA8: 6
A9: 129.50749 | B9: =A9+A9*0.1 -> 142.45824 | G9: 0.11 | H9: 2.38 | I9: 6 | J9: 0.2 | K9: 0.25 | L9: 5.25 | V9: 0.15 | W9: 2.45 | X9: 6.3 | Y9: 0.25 | Z9: 0.3 | AA9: 5.3
A10: 130.81471 | B10: =A10+A10*0.1 -> 143.89618 | D10: 7 | E10: ADT 420 | F10: 45701 | G10: 0.2 | H10: 1.54 | I10: 5 | J10: 0.45 | K10: 0.3 | L10: 5 | M10: =SUM(G10:L10) -> 12.49 | N10: =SUM(G11:L11) -> 13.02 | O10: =SUM(G12:L12) -> 14.51 | P10: =(M10+N10+O10)/3 -> 13.34 | Q10: =60/P10*45 -> 202.3988 | S10: 7 | T10: ADT 420 | U10: 45701 | V10: 0.22 | W10: 2.25 | X10: 5.32 | Y10: 0.45 | Z10: 0.33 | AA10: 5.6 | AB10: =SUM(V10:AA10) -> 14.17 | AC10: =SUM(V11:AA11) -> 13.74 | AD10: =SUM(V12:AA12) -> 14.63 | AE10: =(AB10+AC10+AD10)/3 -> 14.18 | AF10: =60/AE10*45 -> 190.40903
A11: 115.71429 | B11: =A11+A11*0.1 -> 127.28571 | G11: 0.2 | H11: 2 | I11: 5 | J11: 0.28 | K11: 0.29 | L11: 5.25 | V11: 0.24 | W11: 2.27 | X11: 5.3 | Y11: 0.31 | Z11: 0.32 | AA11: 5.3
A12: 136.11403 | B12: =A12+A12*0.1 -> 149.72543 | G12: 0.15 | H12: 2.34 | I12: 6 | J12: 0.25 | K12: 0.28 | L12: 5.49 | V12: 0.2 | W12: 2.34 | X12: 6 | Y12: 0.28 | Z12: 0.31 | AA12: 5.5
A13: 114.11321 | B13: =A13+A13*0.1 -> 125.52453 | D13: 3 | E13: ADT 421 | F13: 45696 | G13: 0.16 | H13: 2.01 | I13: 5.26 | J13: 0.28 | K13: 0.3 | L13: 5.1 | M13: =SUM(G13:L13) -> 13.11 | N13: =SUM(G14:L14) -> 13.14 | O13: =SUM(G15:L15) -> 14.32 | P13: =(M13+N13+O13)/3 -> 13.523333 | Q13: =60/P13*45 -> 199.65492 | S13: 3 | T13: ADT 421 | U13: 45696 | V13: 0.18 | W13: 2.29 | X13: 5.26 | Y13: 0.28 | Z13: 0.3 | AA13: 5.4 | AB13: =SUM(V13:AA13) -> 13.71 | AC13: =SUM(V14:AA14) -> 13.99 | AD13: =SUM(V15:AA15) -> 15.09 | AE13: =(AB13+AC13+AD13)/3 -> 14.263333 | AF13: =60/AE13*45 -> 189.29656
G14: 0.16 | H14: 2.15 | I14: 5.07 | J14: 0.43 | K14: 0.33 | L14: 5 | V14: 0.2 | W14: 2.34 | X14: 5.5 | Y14: 0.3 | Z14: 0.35 | AA14: 5.3
G15: 0.33 | H15: 2.24 | I15: 6.2 | J15: 0.15 | K15: 0.35 | L15: 5.05 | V15: 0.24 | W15: 2.31 | X15: 6.2 | Y15: 0.27 | Z15: 0.37 | AA15: 5.7
D16: 11 | E16: ADT 424 | F16: 45702 | G16: 0.12 | H16: 2.18 | I16: 6.55 | J16: 1.19 | K16: 0.29 | L16: 5 | M16: =SUM(G16:L16) -> 15.33 | N16: =SUM(G17:L17) -> 14.08 | O16: =SUM(G18:L18) -> 14.37 | P16: =(M16+N16+O16)/3 -> 14.593333 | Q16: =60/P16*45 -> 185.01599 | S16: 11 | T16: ADT 424 | U16: 45702 | V16: 0.2 | W16: 2.32 | X16: 6.55 | Y16: 0.32 | Z16: 0.32 | AA16: 5.6 | AB16: =SUM(V16:AA16) -> 15.31 | AC16: =SUM(V17:AA17) -> 15.6 | AD16: =SUM(V18:AA18) -> 14.98 | AE16: =(AB16+AC16+AD16)/3 -> 15.296667 | AF16: =60/AE16*45 -> 176.50904
G17: 0.3 | H17: 2.15 | I17: 6.3 | J17: 0.45 | K17: 0.32 | L17: 4.56 | V17: 0.23 | W17: 2.28 | X17: 6.5 | Y17: 0.45 | Z17: 0.34 | AA17: 5.8
G18: 0.23 | H18: 2.03 | I18: 6 | J18: 0.52 | K18: 0.31 | L18: 5.28 | V18: 0.25 | W18: 2.29 | X18: 6.2 | Y18: 0.52 | Z18: 0.35 | AA18: 5.37
D19: 12 | E19: ADT 425 | F19: 45702 | G19: 0.13 | H19: 2.32 | I19: 6.5 | J19: 0.3 | K19: 0.31 | L19: 5.07 | M19: =SUM(G19:L19) -> 14.63 | N19: =SUM(G20:L20) -> 12.71 | O19: =SUM(G21:L21) -> 12.21 | P19: =(M19+N19+O19)/3 -> 13.183333 | Q19: =60/P19*45 -> 204.80405 | S19: 12 | T19: ADT 425 | U19: 45702 | V19: 0.27 | W19: 2.34 | X19: 7.02 | Y19: 0.35 | Z19: 0.34 | AA19: 5.37 | AB19: =SUM(V19:AA19) -> 15.69 | AC19: =SUM(V20:AA20) -> 14.72 | AD19: =SUM(V21:AA21) -> 14.88 | AE19: =(AB19+AC19+AD19)/3 -> 15.096667 | AF19: =60/AE19*45 -> 178.84743
G20: 0.19 | H20: 2.3 | I20: 5.36 | J20: 0.27 | K20: 0.29 | L20: 4.3 | V20: 0.26 | W20: 2.38 | X20: 6 | Y20: 0.33 | Z20: 0.35 | AA20: 5.4
G21: 0.2 | H21: 2 | I21: 5.02 | J21: 0.3 | K21: 0.24 | L21: 4.45 | V21: 0.25 | W21: 2.35 | X21: 5.5 | Y21: 0.4 | Z21: 0.38 | AA21: 6
D22: 2 | E22: ADT 426 | F22: 45695 | G22: 0.22 | H22: 2.1 | I22: 6 | J22: 0.25 | K22: 0.3 | L22: 5.55 | M22: =SUM(G22:L22) -> 14.42 | N22: =SUM(G23:L23) -> 13.89 | O22: =SUM(G24:L24) -> 13.03 | P22: =(M22+N22+O22)/3 -> 13.78 | Q22: =60/P22*45 -> 195.93614 | S22: 2 | T22: ADT 426 | U22: 45695 | V22: 0.25 | W22: 2.4 | X22: 6.2 | Y22: 0.27 | Z22: 0.36 | AA22: 6 | AB22: =SUM(V22:AA22) -> 15.48 | AC22: =SUM(V23:AA23) -> 14.95 | AD22: =SUM(V24:AA24) -> 14.01 | AE22: =(AB22+AC22+AD22)/3 -> 14.813333 | AF22: =60/AE22*45 -> 182.26823
G23: 0.16 | H23: 2.15 | I23: 5.5 | J23: 0.26 | K23: 0.32 | L23: 5.5 | V23: 0.2 | W23: 2.35 | X23: 6 | Y23: 0.26 | Z23: 0.34 | AA23: 5.8
G24: 0.18 | H24: 2 | I24: 5.2 | J24: 0.29 | K24: 0.36 | L24: 5 | V24: 0.22 | W24: 2.33 | X24: 5.8 | Y24: 0.3 | Z24: 0.36 | AA24: 5
D25: 6 | E25: ADT 427 | F25: 45701 | G25: 0.18 | H25: 2.22 | I25: 6 | J25: 0.24 | K25: 0.32 | L25: 5.52 | M25: =SUM(G25:L25) -> 14.48 | N25: =SUM(G26:L26) -> 13.49 | O25: =SUM(G27:L27) -> 14.06 | P25: =(M25+N25+O25)/3 -> 14.01 | Q25: =60/P25*45 -> 192.71949 | S25: 6 | T25: ADT 427 | U25: 45701 | V25: 0.23 | W25: 2.36 | X25: 6.2 | Y25: 0.33 | Z25: 0.36 | AA25: 5.58 | AB25: =SUM(V25:AA25) -> 15.06 | AC25: =SUM(V26:AA26) -> 14.47 | AD25: =SUM(V27:AA27) -> 14.37 | AE25: =(AB25+AC25+AD25)/3 -> 14.633333 | AF25: =60/AE25*45 -> 184.51025
G26: 0.17 | H26: 2 | I26: 5.38 | J26: 0.25 | K26: 0.39 | L26: 5.3 | V26: 0.26 | W26: 2.37 | X26: 5.55 | Y26: 0.3 | Z26: 0.39 | AA26: 5.6
G27: 0.2 | H27: 2.6 | I27: 5.2 | J27: 0.28 | K27: 0.34 | L27: 5.44 | V27: 0.23 | W27: 2.48 | X27: 5.48 | Y27: 0.32 | Z27: 0.36 | AA27: 5.5
D28: 5 | E28: ADT 429 | F28: 45700 | G28: 0.2 | H28: 2 | I28: 5.31 | J28: 0.18 | K28: 0.32 | L28: 5.43 | M28: =SUM(G28:L28) -> 13.44 | N28: =SUM(G29:L29) -> 13.51 | O28: =SUM(G30:L30) -> 14.66 | P28: =(M28+N28+O28)/3 -> 13.87 | Q28: =60/P28*45 -> 194.66474 | S28: 5 | T28: ADT 429 | U28: 45700 | V28: 0.2 | W28: 2.29 | X28: 5.31 | Y28: 0.25 | Z28: 0.36 | AA28: 5.55 | AB28: =SUM(V28:AA28) -> 13.96 | AC28: =SUM(V29:AA29) -> 13.96 | AD28: =SUM(V30:AA30) -> 15.62 | AE28: =(AB28+AC28+AD28)/3 -> 14.513333 | AF28: =60/AE28*45 -> 186.03583
G29: 0.2 | H29: 2.07 | I29: 5.31 | J29: 0.18 | K29: 0.32 | L29: 5.43 | V29: 0.22 | W29: 2.3 | X29: 5.35 | Y29: 0.24 | Z29: 0.35 | AA29: 5.5
G30: 0.15 | H30: 2.02 | I30: 6.42 | J30: 0.31 | K30: 0.37 | L30: 5.39 | V30: 0.25 | W30: 2.31 | X30: 6.38 | Y30: 0.31 | Z30: 0.37 | AA30: 6
D31: 9 | E31: ADT 431 | F31: 45701 | G31: 0.24 | H31: 2.37 | I31: 7.27 | J31: 0.3 | K31: 0.13 | L31: 6 | M31: =SUM(G31:L31) -> 16.31 | N31: =SUM(G32:L32) -> 15.82 | O31: =SUM(G33:L33) -> 14.91 | P31: =(M31+N31+O31)/3 -> 15.68 | Q31: =60/P31*45 -> 172.19388 | S31: 9 | T31: ADT 431 | U31: 45701 | V31: 0.25 | W31: 2.37 | X31: 7.27 | Y31: 0.32 | Z31: 0.3 | AA31: 6 | AB31: =SUM(V31:AA31) -> 16.51 | AC31: =SUM(V32:AA32) -> 15.6 | AD31: =SUM(V33:AA33) -> 15.54 | AE31: =(AB31+AC31+AD31)/3 -> 15.883333 | AF31: =60/AE31*45 -> 169.98951
G32: 0.18 | H32: 2.01 | I32: 6.01 | J32: 1.23 | K32: 0.24 | L32: 6.15 | V32: 0.2 | W32: 2.3 | X32: 6.3 | Y32: 0.31 | Z32: 0.29 | AA32: 6.2
G33: 0.2 | H33: 2.03 | I33: 6.1 | J33: 0.2 | K33: 0.18 | L33: 6.2 | V33: 0.21 | W33: 2.31 | X33: 6.21 | Y33: 0.29 | Z33: 0.27 | AA33: 6.25
D34: 8 | E34: ADT 432 | F34: 45701 | G34: 0.18 | H34: 2.07 | I34: 5.13 | J34: 0.2 | K34: 0.27 | L34: 5.45 | M34: =SUM(G34:L34) -> 13.3 | N34: =SUM(G35:L35) -> 13.58 | O34: =SUM(G36:L36) -> 13.12 | P34: =(M34+N34+O34)/3 -> 13.333333 | Q34: =60/P34*45 -> 202.5 | S34: 8 | T34: ADT 432 | U34: 45701 | V34: 0.21 | W34: 2.33 | X34: 5.3 | Y34: 0.25 | Z34: 0.3 | AA34: 5.5 | AB34: =SUM(V34:AA34) -> 13.89 | AC34: =SUM(V35:AA35) -> 14.08 | AD34: =SUM(V36:AA36) -> 13.81 | AE34: =(AB34+AC34+AD34)/3 -> 13.926667 | AF34: =60/AE34*45 -> 193.87267
G35: 0.15 | H35: 2.15 | I35: 5.46 | J35: 0.3 | K35: 0.32 | L35: 5.2 | V35: 0.2 | W35: 2.3 | X35: 5.5 | Y35: 0.32 | Z35: 0.35 | AA35: 5.41
G36: 0.2 | H36: 2 | I36: 5.14 | J36: 0.2 | K36: 0.26 | L36: 5.32 | V36: 0.22 | W36: 2.32 | X36: 5.25 | Y36: 0.3 | Z36: 0.32 | AA36: 5.4
D37: 10 | E37: ADT 433 | F37: 45701 | G37: 0.2 | H37: 1.47 | I37: 7.05 | J37: 0.25 | K37: 0.24 | L37: 7.11 | M37: =SUM(G37:L37) -> 16.32 | N37: =SUM(G38:L38) -> 15.8 | O37: =SUM(G39:L39) -> 15.58 | P37: =(M37+N37+O37)/3 -> 15.9 | Q37: =60/P37*45 -> 169.81132 | S37: 10 | T37: ADT 433 | U37: 45701 | V37: 0.23 | W37: 2.3 | X37: 7.12 | Y37: 0.3 | Z37: 0.29 | AA37: 7.15 | AB37: =SUM(V37:AA37) -> 17.39 | AC37: =SUM(V38:AA38) -> 16.19 | AD37: =SUM(V39:AA39) -> 16.82 | AE37: =(AB37+AC37+AD37)/3 -> 16.8 | AF37: =60/AE37*45 -> 160.71429
G38: 0.23 | H38: 2.23 | I38: 7.45 | J38: 0.27 | K38: 0.32 | L38: 5.3 | V38: 0.25 | W38: 2.34 | X38: 7.45 | Y38: 0.3 | Z38: 0.35 | AA38: 5.5
G39: 0.19 | H39: 1.53 | I39: 7.3 | J39: 0.28 | K39: 0.28 | L39: 6 | V39: 0.23 | W39: 2.28 | X39: 7.5 | Y39: 0.3 | Z39: 0.31 | AA39: 6.2
P40: =SUM(P7:P39)/12 -> 12.935278 | Q40: =SUM(Q7:Q39)/12 -> 176.0349 | AE40: =SUM(AE7:AE39)/12 -> 13.720833 | AF40: =SUM(AF7:AF39)/12 -> 165.79829

Sheet Fuel Burn
A1: EQUIPMENT | B1: AVG_FUEL_BURN | C1: AVG_HM_KM
A2: HT416 | B2: 0.081980519 | C2: 2464
A3: HT419 | B3: 2.4161074 | C3: 149
A4: HT420 | B4: 1.6855346 | C4: 159
A5: HT421 | B5: 1.6932515 | C5: 163
A6: HT424 | B6: 0.95934959 | C6: 246
A7: HT425 | B7: 2.1075949 | C7: 158
A8: HT426 | B8: 1.4407895 | C8: 152
A9: HT427 | B9: 2.0314465 | C9: 159
A10: HT429 | B10: 1.8300654 | C10: 153
A11: HT431 | B11: 0.68200837 | C11: 239
A12: HT432 | B12: 1.183432 | C12: 169
A13: HT433 | B13: 1.0115607 | C13: 173

Sheet Fuel Ratio
A1: EQUIPMENT | B1: Produktivitas (bcm/Jam) | C1: Produktivitas Simulasi (bcm/Jam) | D1: Fuel Burn (L/Jam) | E1: Fuel Ratio Asli (L/bcm) | F1: Fuel Ratio Simulasi (L/bcm) | G1: Fuel Asli (L/km) | H1: Jarak (km)
A2: HT416 | B2: =Produktivitas!A2 -> 133.41176 | C2: =Produktivitas!B2 -> 146.75294 | D2: 0 | E2: =D2/B2 -> 0 | F2: =D2/C2 -> 0 | G2: ='Fuel Burn'!B2*'Fuel Burn'!C2 -> 202 | H2: 1 | I2: =ABS(E2-F2) -> 0
A3: HT419 | B3: =Produktivitas!A3 -> 129.50749 | C3: =Produktivitas!B3 -> 142.45824 | D3: 0.75680724 | E3: =D3/B3 -> 0.0058437332 | F3: =D3/C3 -> 0.0053124847 | G3: ='Fuel Burn'!B3*'Fuel Burn'!C3 -> 360 | H3: 2 | I3: =ABS(E3-F3) -> 0.00053124847
A4: HT420 | B4: =Produktivitas!A4 -> 136.01199 | C4: =Produktivitas!B4 -> 149.61319 | D4: 0.6555931 | E4: =D4/B4 -> 0.0048201124 | F4: =D4/C4 -> 0.0043819204 | G4: ='Fuel Burn'!B4*'Fuel Burn'!C4 -> 268 | H4: 3 | I4: =ABS(E4-F4) -> 0.00043819204
A5: HT421 | B5: =Produktivitas!A5 -> 134.20118 | C5: =Produktivitas!B5 -> 147.6213 | D5: 0.72897661 | E5: =D5/B5 -> 0.0054319686 | F5: =D5/C5 -> 0.0049381533 | G5: ='Fuel Burn'!B5*'Fuel Burn'!C5 -> 276 | H5: 4 | I5: =ABS(E5-F5) -> 0.00049381533
A6: HT424 | B6: =Produktivitas!A6 -> 124.35915 | C6: =Produktivitas!B6 -> 136.79507 | D6: 0.51319726 | E6: =D6/B6 -> 0.004126735 | F6: =D6/C6 -> 0.0037515773 | G6: ='Fuel Burn'!B6*'Fuel Burn'!C6 -> 236 | H6: 5 | I6: =ABS(E6-F6) -> 0.00037515773
A7: HT425 | B7: =Produktivitas!A7 -> 135.40299 | C7: =Produktivitas!B7 -> 148.94328 | D7: 0.80332291 | E7: =D7/B7 -> 0.0059328301 | F7: =D7/C7 -> 0.0053934819 | G7: ='Fuel Burn'!B7*'Fuel Burn'!C7 -> 333 | H7: 6 | I7: =ABS(E7-F7) -> 0.00053934819
A8: HT426 | B8: =Produktivitas!A8 -> 131.66909 | C8: =Produktivitas!B8 -> 144.83599 | D8: 0.73152883 | E8: =D8/B8 -> 0.0055558131 | F8: =D8/C8 -> 0.0050507392 | G8: ='Fuel Burn'!B8*'Fuel Burn'!C8 -> 219 | H8: 7 | I8: =ABS(E8-F8) -> 0.00050507392
A9: HT427 | B9: =Produktivitas!A9 -> 129.50749 | C9: =Produktivitas!B9 -> 142.45824 | D9: 0.72863835 | E9: =D9/B9 -> 0.0056262253 | F9: =D9/C9 -> 0.0051147503 | G9: ='Fuel Burn'!B9*'Fuel Burn'!C9 -> 323 | H9: 8 | I9: =ABS(E9-F9) -> 0.00051147503
A10: HT429 | B10: =Produktivitas!A10 -> 130.81471 | C10: =Produktivitas!B10 -> 143.89618 | D10: 0.72151266 | E10: =D10/B10 -> 0.0055155316 | F10: =D10/C10 -> 0.0050141197 | G10: ='Fuel Burn'!B10*'Fuel Burn'!C10 -> 280 | H10: 9 | I10: =ABS(E10-F10) -> 0.00050141197
A11: HT431 | B11: =Produktivitas!A11 -> 115.71429 | C11: =Produktivitas!B11 -> 127.28571 | D11: 0.47822129 | E11: =D11/B11 -> 0.0041327766 | F11: =D11/C11 -> 0.0037570696 | G11: ='Fuel Burn'!B11*'Fuel Burn'!C11 -> 163 | H11: 10 | I11: =ABS(E11-F11) -> 0.00037570696
A12: HT432 | B12: =Produktivitas!A12 -> 136.11403 | C12: =Produktivitas!B12 -> 149.72543 | D12: 0.64278595 | E12: =D12/B12 -> 0.0047224078 | F12: =D12/C12 -> 0.004293098 | G12: ='Fuel Burn'!B12*'Fuel Burn'!C12 -> 200 | H12: 11 | I12: =ABS(E12-F12) -> 0.0004293098
A13: HT433 | B13: =Produktivitas!A13 -> 114.11321 | C13: =Produktivitas!B13 -> 125.52453 | D13: 0.61509366 | E13: =D13/B13 -> 0.0053902057 | F13: =D13/C13 -> 0.004900187 | G13: ='Fuel Burn'!B13*'Fuel Burn'!C13 -> 175 | H13: 12 | I13: =ABS(E13-F13) -> 0.0004900187

Sheet Grade
A1: Segmen | B1: Lebar | C1: Panjang | D1: Kemiringan | E1: Kemiringin (10%) | F1: Kemiringin (20%) | G1: Kemiringin (30%) | H1: Kemiringin (40%) | I1: Grade | J1: b | K1: b1 | L1: b2 | M1: b3 | N1: b4 | O1: c | P1: c1 | Q1: c2 | R1: c3 | S1: c4
A2: A-B | B2: 11.3 | C2: 40.4 | D2: 0 | E2: 0 | F2: 0 | G2: 0 | H2: 0 | I2: =D2/C2 -> 0 | J2: =(Parameter!$D$9*COS(Grade!D2)*(Parameter!$D$10+Parameter!$D$11))+(Parameter!$D$9*SIN(Grade!D2)) -> 2.20725 | K2: =(Parameter!$D$9*COS(Grade!E2)*(Parameter!$D$10+Parameter!$D$11))+(Parameter!$D$9*SIN(Grade!E2)) -> 2.20725 | L2: =(Parameter!$D$9*COS(Grade!F2)*(Parameter!$D$10+Parameter!$D$11))+(Parameter!$D$9*SIN(Grade!F2)) -> 2.20725 | M2: =(Parameter!$D$9*COS(Grade!G2)*(Parameter!$D$10+Parameter!$D$11))+(Parameter!$D$9*SIN(Grade!G2)) -> 2.20725 | N2: =(Parameter!$D$9*COS(Grade!H2)*(Parameter!$D$10+Parameter!$D$11))+(Parameter!$D$9*SIN(Grade!H2)) -> 2.20725 | O2: =(Parameter!$D$9*COS(Grade!D2)*(Parameter!$D$10+Parameter!$D$11))-(Parameter!$D$9*SIN(Grade!D2)) -> 2.20725 | P2: =(Parameter!$D$9*COS(Grade!E2)*(Parameter!$D$10+Parameter!$D$11))-(Parameter!$D$9*SIN(Grade!E2)) -> 2.20725 | Q2: =(Parameter!$D$9*COS(Grade!F2)*(Parameter!$D$10+Parameter!$D$11))-(Parameter!$D$9*SIN(Grade!F2)) -> 2.20725 | R2: =(Parameter!$D$9*COS(Grade!G2)*(Parameter!$D$10+Parameter!$D$11))-(Parameter!$D$9*SIN(Grade!G2)) -> 2.20725 | S2: =(Parameter!$D$9*COS(Grade!H2)*(Parameter!$D$10+Parameter!$D$11))-(Parameter!$D$9*SIN(Grade!H2)) -> 2.20725
A3: B-C1 | B3: 7.6 | C3: 128.3 | D3: 0 | E3: 0 | F3: 0 | G3: 0 | H3: 0 | I3: =D3/C3 -> 0 | J3: =(Parameter!$D$9*COS(Grade!D3)*(Parameter!$D$10+Parameter!$D$11))+(Parameter!$D$9*SIN(Grade!D3)) -> 2.20725 | K3: =(Parameter!$D$9*COS(Grade!E3)*(Parameter!$D$10+Parameter!$D$11))+(Parameter!$D$9*SIN(Grade!E3)) -> 2.20725 | L3: =(Parameter!$D$9*COS(Grade!F3)*(Parameter!$D$10+Parameter!$D$11))+(Parameter!$D$9*SIN(Grade!F3)) -> 2.20725 | M3: =(Parameter!$D$9*COS(Grade!G3)*(Parameter!$D$10+Parameter!$D$11))+(Parameter!$D$9*SIN(Grade!G3)) -> 2.20725 | N3: =(Parameter!$D$9*COS(Grade!H3)*(Parameter!$D$10+Parameter!$D$11))+(Parameter!$D$9*SIN(Grade!H3)) -> 2.20725 | O3: =(Parameter!$D$9*COS(Grade!D3)*(Parameter!$D$10+Parameter!$D$11))-(Parameter!$D$9*SIN(Grade!D3)) -> 2.20725 | P3: =(Parameter!$D$9*COS(Grade!E3)*(Parameter!$D$10+Parameter!$D$11))-(Parameter!$D$9*SIN(Grade!E3)) -> 2.20725 | Q3: =(Parameter!$D$9*COS(Grade!F3)*(Parameter!$D$10+Parameter!$D$11))-(Parameter!$D$9*SIN(Grade!F3)) -> 2.20725 | R3: =(Parameter!$D$9*COS(Grade!G3)*(Parameter!$D$10+Parameter!$D$11))-(Parameter!$D$9*SIN(Grade!G3)) -> 2.20725 | S3: =(Parameter!$D$9*COS(Grade!H3)*(Parameter!$D$10+Parameter!$D$11))-(Parameter!$D$9*SIN(Grade!H3)) -> 2.20725
A4: C1-C2 | B4: 9 | C4: 33 | D4: 11.22 | E4: =C4*0.1 -> 3.3 | F4: =C4*0.2 -> 6.6 | G4: =C4*0.3 -> 9.9 | H4: =C4*0.4 -> 13.2 | I4: =D4/C4 -> 0.34 | J4: =(Parameter!$D$9*COS(Grade!D4)*(Parameter!$D$10+Parameter!$D$11))+(Parameter!$D$9*SIN(Grade!D4)) -> -9.0727697 | K4: =(Parameter!$D$9*COS(Grade!E4)*(Parameter!$D$10+Parameter!$D$11))+(Parameter!$D$9*SIN(Grade!E4)) -> -3.7271 | L4: =(Parameter!$D$9*COS(Grade!F4)*(Parameter!$D$10+Parameter!$D$11))+(Parameter!$D$9*SIN(Grade!F4)) -> 5.1536217 | M4: =(Parameter!$D$9*COS(Grade!G4)*(Parameter!$D$10+Parameter!$D$11))+(Parameter!$D$9*SIN(Grade!G4)) -> -6.4510943 | N4: =(Parameter!$D$9*COS(Grade!H4)*(Parameter!$D$10+Parameter!$D$11))+(Parameter!$D$9*SIN(Grade!H4)) -> 7.5870285 | O4: =(Parameter!$D$9*COS(Grade!D4)*(Parameter!$D$10+Parameter!$D$11))-(Parameter!$D$9*SIN(Grade!D4)) -> 10.055201 | P4: =(Parameter!$D$9*COS(Grade!E4)*(Parameter!$D$10+Parameter!$D$11))-(Parameter!$D$9*SIN(Grade!E4)) -> -0.63212946 | Q4: =(Parameter!$D$9*COS(Grade!F4)*(Parameter!$D$10+Parameter!$D$11))-(Parameter!$D$9*SIN(Grade!F4)) -> -0.95881989 | R4: =(Parameter!$D$9*COS(Grade!G4)*(Parameter!$D$10+Parameter!$D$11))-(Parameter!$D$9*SIN(Grade!G4)) -> 2.5257599 | S4: =(Parameter!$D$9*COS(Grade!H4)*(Parameter!$D$10+Parameter!$D$11))-(Parameter!$D$9*SIN(Grade!H4)) -> -4.0294538
A5: C2-D | B5: 10.5 | C5: 150.7 | D5: 0 | E5: 0 | F5: 0 | G5: 0 | H5: 0 | I5: =D5/C5 -> 0 | J5: =(Parameter!$D$9*COS(Grade!D5)*(Parameter!$D$10+Parameter!$D$11))+(Parameter!$D$9*SIN(Grade!D5)) -> 2.20725 | K5: =(Parameter!$D$9*COS(Grade!E5)*(Parameter!$D$10+Parameter!$D$11))+(Parameter!$D$9*SIN(Grade!E5)) -> 2.20725 | L5: =(Parameter!$D$9*COS(Grade!F5)*(Parameter!$D$10+Parameter!$D$11))+(Parameter!$D$9*SIN(Grade!F5)) -> 2.20725 | M5: =(Parameter!$D$9*COS(Grade!G5)*(Parameter!$D$10+Parameter!$D$11))+(Parameter!$D$9*SIN(Grade!G5)) -> 2.20725 | N5: =(Parameter!$D$9*COS(Grade!H5)*(Parameter!$D$10+Parameter!$D$11))+(Parameter!$D$9*SIN(Grade!H5)) -> 2.20725 | O5: =(Parameter!$D$9*COS(Grade!D5)*(Parameter!$D$10+Parameter!$D$11))-(Parameter!$D$9*SIN(Grade!D5)) -> 2.20725 | P5: =(Parameter!$D$9*COS(Grade!E5)*(Parameter!$D$10+Parameter!$D$11))-(Parameter!$D$9*SIN(Grade!E5)) -> 2.20725 | Q5: =(Parameter!$D$9*COS(Grade!F5)*(Parameter!$D$10+Parameter!$D$11))-(Parameter!$D$9*SIN(Grade!F5)) -> 2.20725 | R5: =(Parameter!$D$9*COS(Grade!G5)*(Parameter!$D$10+Parameter!$D$11))-(Parameter!$D$9*SIN(Grade!G5)) -> 2.20725 | S5: =(Parameter!$D$9*COS(Grade!H5)*(Parameter!$D$10+Parameter!$D$11))-(Parameter!$D$9*SIN(Grade!H5)) -> 2.20725
A6: D-E | B6: 69 | C6: 452.4 | D6: 0 | E6: 0 | F6: 0 | G6: 0 | H6: 0 | I6: =D6/C6 -> 0 | J6: =(Parameter!$D$9*COS(Grade!D6)*(Parameter!$D$10+Parameter!$D$11))+(Parameter!$D$9*SIN(Grade!D6)) -> 2.20725 | K6: =(Parameter!$D$9*COS(Grade!E6)*(Parameter!$D$10+Parameter!$D$11))+(Parameter!$D$9*SIN(Grade!E6)) -> 2.20725 | L6: =(Parameter!$D$9*COS(Grade!F6)*(Parameter!$D$10+Parameter!$D$11))+(Parameter!$D$9*SIN(Grade!F6)) -> 2.20725 | M6: =(Parameter!$D$9*COS(Grade!G6)*(Parameter!$D$10+Parameter!$D$11))+(Parameter!$D$9*SIN(Grade!G6)) -> 2.20725 | N6: =(Parameter!$D$9*COS(Grade!H6)*(Parameter!$D$10+Parameter!$D$11))+(Parameter!$D$9*SIN(Grade!H6)) -> 2.20725 | O6: =(Parameter!$D$9*COS(Grade!D6)*(Parameter!$D$10+Parameter!$D$11))-(Parameter!$D$9*SIN(Grade!D6)) -> 2.20725 | P6: =(Parameter!$D$9*COS(Grade!E6)*(Parameter!$D$10+Parameter!$D$11))-(Parameter!$D$9*SIN(Grade!E6)) -> 2.20725 | Q6: =(Parameter!$D$9*COS(Grade!F6)*(Parameter!$D$10+Parameter!$D$11))-(Parameter!$D$9*SIN(Grade!F6)) -> 2.20725 | R6: =(Parameter!$D$9*COS(Grade!G6)*(Parameter!$D$10+Parameter!$D$11))-(Parameter!$D$9*SIN(Grade!G6)) -> 2.20725 | S6: =(Parameter!$D$9*COS(Grade!H6)*(Parameter!$D$10+Parameter!$D$11))-(Parameter!$D$9*SIN(Grade!H6)) -> 2.20725

Sheet Parameter
A1: Parameter | B1: Satuan | C1: Nama | D1: Nilai 1 | E1: Nilai 2
A2: Koefisien Hambatan Aerodinamis | B2: - | C2: Cd | D2: 0.8 | E2: 0.9
A3: densitas udara | B3: (kg/m3) | C3: rho | D3: 1.222
A4: luas penampang bagian depan alat angkut | B4: m2 | C4: AF | D4: 5.25
A5: kecepatan alat angkut bermuatan rata-rata dari area pemuatan sampai dengan area penimbunan | B5: m/s | C5: Va | D5: 45
A6: kecepatan alat angkut kosongan rata-rata dari area penimbunan sampai ke area pemuatan | B6: m/s | C6: Vk | D6: 55
A7: berat alat angkut bermuatan | B7: kg | C7: Wa | D7: 98750
A8: berat alat angkut kosong | B8: kg | C8: Wk | D8: 43750
A9: percepatan gravitasi | B9: m/s2 | C9: g | D9: 9.81
A10: koefisien gesekan ban dengan permukaan jalan | B10: - | C10: f | D10: 0.2 | E10: 0.3
A11: koefisien tahanan gulir | B11: - | C11: Crr | D11: 0.025 | E11: 0.03
A12: percepatan | B12: m/s | C12: a | D12: =(D2*D3*D4)/2 -> 2.5662

Sheet Kecepatan
A1: Segmen | B1: Kecepatan Muatan | C1: Kecepatan Kosongan
A2: A-B | B2: 40 | C2: 50
A3: B-C1 | B3: 40 | C3: 50
A4: C1-C2 | B4: 30 | C4: 40
A5: C2-D | B5: 40 | C5: 50
A6: D-E | B6: 45 | C6: 55

Sheet Regresi HT416
A1: Segmen | B1: Grade | C1: P(kW) | F1: Segmen | G1: P(%) | I1: Fuel consumption | L1: Segmen | M1: Grade | N1: P(kW) | Q1: Segmen | R1: P(%) | T1: Fuel consumption | W1: Segmen | X1: Grade | Y1: P(kW) | AB1: Segmen | AC1: P(%) | AE1: Fuel consumption | AH1: Segmen | AI1: Grade | AJ1: P(kW) | AM1: Segmen | AN1: P(%) | AP1: Fuel consumption | AS1: Segmen | AT1: Grade | AU1: P(kW) | AX1: Segmen | AY1: P(%) | BA1: Fuel consumption
C2: Pa | D2: Pk | G2: Pa | H2: Pk | I2: Muatan | J2: Kosongan | N2: Pa | O2: Pk | R2: Pa | S2: Pk | T2: Muatan | U2: Kosongan | Y2: Pa | Z2: Pk | AC2: Pa | AD2: Pk | AE2: Muatan | AF2: Kosongan | AJ2: Pa | AK2: Pk | AN2: Pa | AO2: Pk | AP2: Muatan | AQ2: Kosongan | AU2: Pa | AV2: Pk | AY2: Pa | AZ2: Pk | BA2: Muatan | BB2: Kosongan
A3: A-B | B3: =Grade!I2 -> 0 | C3: =Kecepatan!B2*(Parameter!$D$12*Kecepatan!B2^2)+(Grade!J2*Parameter!$D$7) -> 382202.74 | D3: =Kecepatan!C2*(Parameter!$D$12*Kecepatan!C2^2)+(Grade!O2*Parameter!$D$8) -> 417342.19 | F3: A-B | G3: =C3/$C$9 -> 0.1212777 | H3: =D3/$C$9 -> 0.13242788 | I3: =G3*'Fuel Ratio'!$D$2 -> 0 | J3: =H3*'Fuel Ratio'!$D$2 -> 0 | L3: A-B | M3: =Grade!T2 -> 0 | N3: =Kecepatan!B2*(Parameter!$D$12*Kecepatan!B2^2)+(Grade!K2*Parameter!$D$7) -> 382202.74 | O3: =Kecepatan!C2*(Parameter!$D$12*Kecepatan!C2^2)+(Grade!P2*Parameter!$D$7) -> 538740.94 | Q3: A-B | R3: =N3/$N$9 -> 0.10435257 | S3: =O3/$N$9 -> 0.1470921 | T3: =R3*'Fuel Ratio'!$D$2 -> 0 | U3: =S3*'Fuel Ratio'!$D$2 -> 0 | W3: A-B | X3: =Grade!AE2 -> 0 | Y3: =Kecepatan!B2*(Parameter!$D$12*Kecepatan!B2^2)+(Grade!L2*Parameter!$D$7) -> 382202.74 | Z3: =Kecepatan!C2*(Parameter!$D$12*Kecepatan!C2^2)+(Grade!Q2*Parameter!$D$7) -> 538740.94 | AB3: A-B | AC3: =Y3/$Y$9 -> 0.084796002 | AD3: =Z3/$Y$9 -> 0.11952577 | AE3: =AC3*'Fuel Ratio'!$D$2 -> 0 | AF3: =AD3*'Fuel Ratio'!$D$2 -> 0 | AH3: A-B | AI3: =Grade!AP2 -> 0 | AJ3: =Kecepatan!B2*(Parameter!$D$12*Kecepatan!B2^2)+(Grade!M2*Parameter!$D$7) -> 382202.74 | AK3: =Kecepatan!C2*(Parameter!$D$12*Kecepatan!C2^2)+(Grade!R2*Parameter!$D$7) -> 538740.94 | AM3: A-B | AN3: =AJ3/$AJ$9 -> 0.10314592 | AO3: =AK3/$AJ$9 -> 0.14539123 | AP3: =AN3*'Fuel Ratio'!$D$2 -> 0 | AQ3: =AO3*'Fuel Ratio'!$D$2 -> 0 | AS3: A-B | AT3: =Grade!BA2 -> 0 | AU3: =Kecepatan!B2*(Parameter!$D$12*Kecepatan!B2^2)+(Grade!N2*Parameter!$D$7) -> 382202.74 | AV3: =Kecepatan!C2*(Parameter!$D$12*Kecepatan!C2^2)+(Grade!S2*Parameter!$D$7) -> 538740.94 | AX3: A-B | AY3: =AU3/$AU$9 -> 0.08599659 | AZ3: =AV3/$AU$9 -> 0.12121808 | BA3: =AY3*'Fuel Ratio'!$D$2 -> 0 | BB3: =AZ3*'Fuel Ratio'!$D$2 -> 0
A4: B-C1 | B4: =Grade!I3 -> 0 | C4: =Kecepatan!B3*(Parameter!$D$12*Kecepatan!B3^2)+(Grade!J3*Parameter!$D$7) -> 382202.74 | D4: =Kecepatan!C3*(Parameter!$D$12*Kecepatan!C3^2)+(Grade!O3*Parameter!$D$8) -> 417342.19 | F4: B-C1 | G4: =C4/$C$9 -> 0.1212777 | H4: =D4/$C$9 -> 0.13242788 | I4: =G4*'Fuel Ratio'!$D$2 -> 0 | J4: =H4*'Fuel Ratio'!$D$2 -> 0 | L4: B-C1 | M4: =Grade!T3 -> 0 | N4: =Kecepatan!B3*(Parameter!$D$12*Kecepatan!B3^2)+(Grade!K3*Parameter!$D$7) -> 382202.74 | O4: =Kecepatan!C3*(Parameter!$D$12*Kecepatan!C3^2)+(Grade!P3*Parameter!$D$7) -> 538740.94 | Q4: B-C1 | R4: =N4/$N$9 -> 0.10435257 | S4: =O4/$N$9 -> 0.1470921 | T4: =R4*'Fuel Ratio'!$D$2 -> 0 | U4: =S4*'Fuel Ratio'!$D$2 -> 0 | W4: B-C1 | X4: =Grade!AE3 -> 0 | Y4: =Kecepatan!B3*(Parameter!$D$12*Kecepatan!B3^2)+(Grade!L3*Parameter!$D$7) -> 382202.74 | Z4: =Kecepatan!C3*(Parameter!$D$12*Kecepatan!C3^2)+(Grade!Q3*Parameter!$D$7) -> 538740.94 | AB4: B-C1 | AC4: =Y4/$Y$9 -> 0.084796002 | AD4: =Z4/$Y$9 -> 0.11952577 | AE4: =AC4*'Fuel Ratio'!$D$2 -> 0 | AF4: =AD4*'Fuel Ratio'!$D$2 -> 0 | AH4: B-C1 | AI4: =Grade!AP3 -> 0 | AJ4: =Kecepatan!B3*(Parameter!$D$12*Kecepatan!B3^2)+(Grade!M3*Parameter!$D$7) -> 382202.74 | AK4: =Kecepatan!C3*(Parameter!$D$12*Kecepatan!C3^2)+(Grade!R3*Parameter!$D$7) -> 538740.94 | AM4: B-C1 | AN4: =AJ4/$AJ$9 -> 0.10314592 | AO4: =AK4/$AJ$9 -> 0.14539123 | AP4: =AN4*'Fuel Ratio'!$D$2 -> 0 | AQ4: =AO4*'Fuel Ratio'!$D$2 -> 0 | AS4: B-C1 | AT4: =Grade!BA3 -> 0 | AU4: =Kecepatan!B3*(Parameter!$D$12*Kecepatan!B3^2)+(Grade!N3*Parameter!$D$7) -> 382202.74 | AV4: =Kecepatan!C3*(Parameter!$D$12*Kecepatan!C3^2)+(Grade!S3*Parameter!$D$7) -> 538740.94 | AX4: B-C1 | AY4: =AU4/$AU$9 -> 0.08599659 | AZ4: =AV4/$AU$9 -> 0.12121808 | BA4: =AY4*'Fuel Ratio'!$D$2 -> 0 | BB4: =AZ4*'Fuel Ratio'!$D$2 -> 0
A5: C1-C2 | B5: =Grade!I4 -> 0.34 | C5: =Kecepatan!B4*(Parameter!$D$12*Kecepatan!B4^2)+(Grade!J4*Parameter!$D$7) -> -826648.61 | D5: =Kecepatan!C4*(Parameter!$D$12*Kecepatan!C4^2)+(Grade!O4*Parameter!$D$8) -> 604151.86 | F5: C1-C2 | G5: =C5/$C$9 -> -0.26230592 | H5: =D5/$C$9 -> 0.19170492 | I5: =G5*'Fuel Ratio'!$D$2 -> 0 | J5: =H5*'Fuel Ratio'!$D$2 -> 0 | L5: C1-C2 | M5: 0.1 | N5: =Kecepatan!B4*(Parameter!$D$12*Kecepatan!B4^2)+(Grade!K4*Parameter!$D$7) -> -298763.72 | O5: =Kecepatan!C4*(Parameter!$D$12*Kecepatan!C4^2)+(Grade!P4*Parameter!$D$7) -> 101814.02 | Q5: C1-C2 | R5: =N5/$N$9 -> -0.08157127 | S5: =O5/$N$9 -> 0.027798216 | T5: =R5*'Fuel Ratio'!$D$2 -> 0 | U5: =S5*'Fuel Ratio'!$D$2 -> 0 | W5: C1-C2 | X5: 0.2 | Y5: =Kecepatan!B4*(Parameter!$D$12*Kecepatan!B4^2)+(Grade!L4*Parameter!$D$7) -> 578207.54 | Z5: =Kecepatan!C4*(Parameter!$D$12*Kecepatan!C4^2)+(Grade!Q4*Parameter!$D$7) -> 69553.336 | AB5: C1-C2 | AC5: =Y5/$Y$9 -> 0.12828188 | AD5: =Z5/$Y$9 -> 0.015431195 | AE5: =AC5*'Fuel Ratio'!$D$2 -> 0 | AF5: =AD5*'Fuel Ratio'!$D$2 -> 0 | AH5: C1-C2 | AI5: 0.3 | AJ5: =Kecepatan!B4*(Parameter!$D$12*Kecepatan!B4^2)+(Grade!M4*Parameter!$D$7) -> -567758.16 | AK5: =Kecepatan!C4*(Parameter!$D$12*Kecepatan!C4^2)+(Grade!R4*Parameter!$D$7) -> 413655.59 | AM5: C1-C2 | AN5: =AJ5/$AJ$9 -> -0.15322218 | AO5: =AK5/$AJ$9 -> 0.11163417 | AP5: =AN5*'Fuel Ratio'!$D$2 -> 0 | AQ5: =AO5*'Fuel Ratio'!$D$2 -> 0 | AS5: C1-C2 | AT5: 0.4 | AU5: =Kecepatan!B4*(Parameter!$D$12*Kecepatan!B4^2)+(Grade!N4*Parameter!$D$7) -> 818506.47 | AV5: =Kecepatan!C4*(Parameter!$D$12*Kecepatan!C4^2)+(Grade!S4*Parameter!$D$7) -> -233671.76 | AX5: C1-C2 | AY5: =AU5/$AU$9 -> 0.18416604 | AZ5: =AV5/$AU$9 -> -0.052576742 | BA5: =AY5*'Fuel Ratio'!$D$2 -> 0 | BB5: =AZ5*'Fuel Ratio'!$D$2 -> 0
A6: C2-D | B6: =Grade!I5 -> 0 | C6: =Kecepatan!B5*(Parameter!$D$12*Kecepatan!B5^2)+(Grade!J5*Parameter!$D$7) -> 382202.74 | D6: =Kecepatan!C5*(Parameter!$D$12*Kecepatan!C5^2)+(Grade!O5*Parameter!$D$8) -> 417342.19 | F6: C2-D | G6: =C6/$C$9 -> 0.1212777 | H6: =D6/$C$9 -> 0.13242788 | I6: =G6*'Fuel Ratio'!$D$2 -> 0 | J6: =H6*'Fuel Ratio'!$D$2 -> 0 | L6: C2-D | M6: =Grade!T5 -> 0 | N6: =Kecepatan!B5*(Parameter!$D$12*Kecepatan!B5^2)+(Grade!K5*Parameter!$D$7) -> 382202.74 | O6: =Kecepatan!C5*(Parameter!$D$12*Kecepatan!C5^2)+(Grade!P5*Parameter!$D$7) -> 538740.94 | Q6: C2-D | R6: =N6/$N$9 -> 0.10435257 | S6: =O6/$N$9 -> 0.1470921 | T6: =R6*'Fuel Ratio'!$D$2 -> 0 | U6: =S6*'Fuel Ratio'!$D$2 -> 0 | W6: C2-D | X6: =Grade!AE5 -> 0 | Y6: =Kecepatan!B5*(Parameter!$D$12*Kecepatan!B5^2)+(Grade!L5*Parameter!$D$7) -> 382202.74 | Z6: =Kecepatan!C5*(Parameter!$D$12*Kecepatan!C5^2)+(Grade!Q5*Parameter!$D$7) -> 538740.94 | AB6: C2-D | AC6: =Y6/$Y$9 -> 0.084796002 | AD6: =Z6/$Y$9 -> 0.11952577 | AE6: =AC6*'Fuel Ratio'!$D$2 -> 0 | AF6: =AD6*'Fuel Ratio'!$D$2 -> 0 | AH6: C2-D | AI6: =Grade!AP5 -> 0 | AJ6: =Kecepatan!B5*(Parameter!$D$12*Kecepatan!B5^2)+(Grade!M5*Parameter!$D$7) -> 382202.74 | AK6: =Kecepatan!C5*(Parameter!$D$12*Kecepatan!C5^2)+(Grade!R5*Parameter!$D$7) -> 538740.94 | AM6: C2-D | AN6: =AJ6/$AJ$9 -> 0.10314592 | AO6: =AK6/$AJ$9 -> 0.14539123 | AP6: =AN6*'Fuel Ratio'!$D$2 -> 0 | AQ6: =AO6*'Fuel Ratio'!$D$2 -> 0 | AS6: C2-D | AT6: =Grade!BA5 -> 0 | AU6: =Kecepatan!B5*(Parameter!$D$12*Kecepatan!B5^2)+(Grade!N5*Parameter!$D$7) -> 382202.74 | AV6: =Kecepatan!C5*(Parameter!$D$12*Kecepatan!C5^2)+(Grade!S5*Parameter!$D$7) -> 538740.94 | AX6: C2-D | AY6: =AU6/$AU$9 -> 0.08599659 | AZ6: =AV6/$AU$9 -> 0.12121808 | BA6: =AY6*'Fuel Ratio'!$D$2 -> 0 | BB6: =AZ6*'Fuel Ratio'!$D$2 -> 0
A7: D-E | B7: =Grade!I6 -> 0 | C7: =Kecepatan!B6*(Parameter!$D$12*Kecepatan!B6^2)+(Grade!J6*Parameter!$D$7) -> 451810.91 | D7: =Kecepatan!C6*(Parameter!$D$12*Kecepatan!C6^2)+(Grade!O6*Parameter!$D$8) -> 523518.71 | F7: D-E | G7: =C7/$C$9 -> 0.14336524 | H7: =D7/$C$9 -> 0.16611902 | I7: =G7*'Fuel Ratio'!$D$2 -> 0 | J7: =H7*'Fuel Ratio'!$D$2 -> 0 | L7: D-E | M7: =Grade!T6 -> 0 | N7: =Kecepatan!B6*(Parameter!$D$12*Kecepatan!B6^2)+(Grade!K6*Parameter!$D$7) -> 451810.91 | O7: =Kecepatan!C6*(Parameter!$D$12*Kecepatan!C6^2)+(Grade!P6*Parameter!$D$7) -> 644917.46 | Q7: D-E | R7: =N7/$N$9 -> 0.12335765 | S7: =O7/$N$9 -> 0.17608141 | T7: =R7*'Fuel Ratio'!$D$2 -> 0 | U7: =S7*'Fuel Ratio'!$D$2 -> 0 | W7: D-E | X7: =Grade!AE6 -> 0 | Y7: =Kecepatan!B6*(Parameter!$D$12*Kecepatan!B6^2)+(Grade!L6*Parameter!$D$7) -> 451810.91 | Z7: =Kecepatan!C6*(Parameter!$D$12*Kecepatan!C6^2)+(Grade!Q6*Parameter!$D$7) -> 644917.46 | AB7: D-E | AC7: =Y7/$Y$9 -> 0.10023936 | AD7: =Z7/$Y$9 -> 0.14308224 | AE7: =AC7*'Fuel Ratio'!$D$2 -> 0 | AF7: =AD7*'Fuel Ratio'!$D$2 -> 0 | AH7: D-E | AI7: =Grade!AP6 -> 0 | AJ7: =Kecepatan!B6*(Parameter!$D$12*Kecepatan!B6^2)+(Grade!M6*Parameter!$D$7) -> 451810.91 | AK7: =Kecepatan!C6*(Parameter!$D$12*Kecepatan!C6^2)+(Grade!R6*Parameter!$D$7) -> 644917.46 | AM7: D-E | AN7: =AJ7/$AJ$9 -> 0.12193123 | AO7: =AK7/$AJ$9 -> 0.17404533 | AP7: =AN7*'Fuel Ratio'!$D$2 -> 0 | AQ7: =AO7*'Fuel Ratio'!$D$2 -> 0 | AS7: D-E | AT7: =Grade!BA6 -> 0 | AU7: =Kecepatan!B6*(Parameter!$D$12*Kecepatan!B6^2)+(Grade!N6*Parameter!$D$7) -> 451810.91 | AV7: =Kecepatan!C6*(Parameter!$D$12*Kecepatan!C6^2)+(Grade!S6*Parameter!$D$7) -> 644917.46 | AX7: D-E | AY7: =AU7/$AU$9 -> 0.10165861 | AZ7: =AV7/$AU$9 -> 0.14510807 | BA7: =AY7*'Fuel Ratio'!$D$2 -> 0 | BB7: =AZ7*'Fuel Ratio'!$D$2 -> 0
A8: Total | C8: =SUM(C3:C7) -> 771770.51 | D8: =SUM(D3:D7) -> 2379697.1 | F8: Total | I8: =SUM(I3:I7) -> 0 | J8: =SUM(J3:J7) -> 0 | L8: Total | N8: =SUM(N3:N7) -> 1299655.4 | O8: =SUM(O3:O7) -> 2362954.3 | Q8: Total | T8: =SUM(T3:T7) -> 0 | U8: =SUM(U3:U7) -> 0 | W8: Total | Y8: =SUM(Y3:Y7) -> 2176626.7 | Z8: =SUM(Z3:Z7) -> 2330693.6 | AB8: Total | AE8: =SUM(AE3:AE7) -> 0 | AF8: =SUM(AF3:AF7) -> 0 | AH8: Total | AJ8: =SUM(AJ3:AJ7) -> 1030661 | AK8: =SUM(AK3:AK7) -> 2674795.9 | AM8: Total | AP8: =SUM(AP3:AP7) -> 0 | AQ8: =SUM(AQ3:AQ7) -> 0 | AS8: Total | AU8: =SUM(AU3:AU7) -> 2416925.6 | AV8: =SUM(AV3:AV7) -> 2027468.5 | AX8: Total | BA8: =SUM(BA3:BA7) -> 0 | BB8: =SUM(BB3:BB7) -> 0
C9: =SUM(C8:D8) -> 3151467.6 | I9: =SUM(I8:J8) -> 0 | N9: =SUM(N8:O8) -> 3662609.7 | T9: =SUM(T8:U8) -> 0 | Y9: =SUM(Y8:Z8) -> 4507320.3 | AE9: =SUM(AE8:AF8) -> 0 | AJ9: =SUM(AJ8:AK8) -> 3705456.8 | AP9: =SUM(AP8:AQ8) -> 0 | AU9: =SUM(AU8:AV8) -> 4444394.1 | BA9: =SUM(BA8:BB8) -> 0

Sheet Regresi HT419
A1: Segmen | B1: Grade | C1: P(kW) | F1: Segmen | G1: P(%) | I1: Fuel consumption | L1: Segmen | M1: Grade | N1: P(kW) | Q1: Segmen | R1: P(%) | T1: Fuel consumption | W1: Segmen | X1: Grade | Y1: P(kW) | AB1: Segmen | AC1: P(%) | AE1: Fuel consumption | AH1: Segmen | AI1: Grade | AJ1: P(kW) | AM1: Segmen | AN1: P(%) | AP1: Fuel consumption | AS1: Segmen | AT1: Grade | AU1: P(kW) | AX1: Segmen | AY1: P(%) | BA1: Fuel consumption
C2: Pa | D2: Pk | G2: Pa | H2: Pk | I2: Muatan | J2: Kosongan | N2: Pa | O2: Pk | R2: Pa | S2: Pk | T2: Muatan | U2: Kosongan | Y2: Pa | Z2: Pk | AC2: Pa | AD2: Pk | AE2: Muatan | AF2: Kosongan | AJ2: Pa | AK2: Pk | AN2: Pa | AO2: Pk | AP2: Muatan | AQ2: Kosongan | AU2: Pa | AV2: Pk | AY2: Pa | AZ2: Pk | BA2: Muatan | BB2: Kosongan
A3: A-B | B3: =Grade!I2 -> 0 | C3: =Kecepatan!B2*(Parameter!$D$12*Kecepatan!B2^2)+(Grade!J2*Parameter!$D$7) -> 382202.74 | D3: =Kecepatan!C2*(Parameter!$D$12*Kecepatan!C2^2)+(Grade!O2*Parameter!$D$8) -> 417342.19 | F3: A-B | G3: =C3/$C$9 -> 0.1212777 | H3: =D3/$C$9 -> 0.13242788 | I3: =G3*'Fuel Ratio'!$D$3 -> 0.091783839 | J3: =H3*'Fuel Ratio'!$D$3 -> 0.10022238 | L3: A-B | M3: =Grade!T2 -> 0 | N3: =Kecepatan!B2*(Parameter!$D$12*Kecepatan!B2^2)+(Grade!K2*Parameter!$D$7) -> 382202.74 | O3: =Kecepatan!C2*(Parameter!$D$12*Kecepatan!C2^2)+(Grade!P2*Parameter!$D$7) -> 538740.94 | Q3: A-B | R3: =N3/$N$9 -> 0.10435257 | S3: =O3/$N$9 -> 0.1470921 | T3: =R3*'Fuel Ratio'!$D$3 -> 0.078974781 | U3: =S3*'Fuel Ratio'!$D$3 -> 0.11132036 | W3: A-B | X3: =Grade!AE2 -> 0 | Y3: =Kecepatan!B2*(Parameter!$D$12*Kecepatan!B2^2)+(Grade!L2*Parameter!$D$7) -> 382202.74 | Z3: =Kecepatan!C2*(Parameter!$D$12*Kecepatan!C2^2)+(Grade!Q2*Parameter!$D$7) -> 538740.94 | AB3: A-B | AC3: =Y3/$Y$9 -> 0.084796002 | AD3: =Z3/$Y$9 -> 0.11952577 | AE3: =AC3*'Fuel Ratio'!$D$3 -> 0.064174228 | AF3: =AD3*'Fuel Ratio'!$D$3 -> 0.09045797 | AH3: A-B | AI3: =Grade!AP2 -> 0 | AJ3: =Kecepatan!B2*(Parameter!$D$12*Kecepatan!B2^2)+(Grade!M2*Parameter!$D$7) -> 382202.74 | AK3: =Kecepatan!C2*(Parameter!$D$12*Kecepatan!C2^2)+(Grade!R2*Parameter!$D$7) -> 538740.94 | AM3: A-B | AN3: =AJ3/$AJ$9 -> 0.10314592 | AO3: =AK3/$AJ$9 -> 0.14539123 | AP3: =AN3*'Fuel Ratio'!$D$3 -> 0.078061576 | AQ3: =AO3*'Fuel Ratio'!$D$3 -> 0.11003314 | AS3: A-B | AT3: =Grade!BA2 -> 0 | AU3: =Kecepatan!B2*(Parameter!$D$12*Kecepatan!B2^2)+(Grade!N2*Parameter!$D$7) -> 382202.74 | AV3: =Kecepatan!C2*(Parameter!$D$12*Kecepatan!C2^2)+(Grade!S2*Parameter!$D$7) -> 538740.94 | AX3: A-B | AY3: =AU3/$AU$9 -> 0.08599659 | AZ3: =AV3/$AU$9 -> 0.12121808 | BA3: =AY3*'Fuel Ratio'!$D$3 -> 0.065082842 | BB3: =AZ3*'Fuel Ratio'!$D$3 -> 0.091738724
A4: B-C1 | B4: =Grade!I3 -> 0 | C4: =Kecepatan!B3*(Parameter!$D$12*Kecepatan!B3^2)+(Grade!J3*Parameter!$D$7) -> 382202.74 | D4: =Kecepatan!C3*(Parameter!$D$12*Kecepatan!C3^2)+(Grade!O3*Parameter!$D$8) -> 417342.19 | F4: B-C1 | G4: =C4/$C$9 -> 0.1212777 | H4: =D4/$C$9 -> 0.13242788 | I4: =G4*'Fuel Ratio'!$D$3 -> 0.091783839 | J4: =H4*'Fuel Ratio'!$D$3 -> 0.10022238 | L4: B-C1 | M4: =Grade!T3 -> 0 | N4: =Kecepatan!B3*(Parameter!$D$12*Kecepatan!B3^2)+(Grade!K3*Parameter!$D$7) -> 382202.74 | O4: =Kecepatan!C3*(Parameter!$D$12*Kecepatan!C3^2)+(Grade!P3*Parameter!$D$7) -> 538740.94 | Q4: B-C1 | R4: =N4/$N$9 -> 0.10435257 | S4: =O4/$N$9 -> 0.1470921 | T4: =R4*'Fuel Ratio'!$D$3 -> 0.078974781 | U4: =S4*'Fuel Ratio'!$D$3 -> 0.11132036 | W4: B-C1 | X4: =Grade!AE3 -> 0 | Y4: =Kecepatan!B3*(Parameter!$D$12*Kecepatan!B3^2)+(Grade!L3*Parameter!$D$7) -> 382202.74 | Z4: =Kecepatan!C3*(Parameter!$D$12*Kecepatan!C3^2)+(Grade!Q3*Parameter!$D$7) -> 538740.94 | AB4: B-C1 | AC4: =Y4/$Y$9 -> 0.084796002 | AD4: =Z4/$Y$9 -> 0.11952577 | AE4: =AC4*'Fuel Ratio'!$D$3 -> 0.064174228 | AF4: =AD4*'Fuel Ratio'!$D$3 -> 0.09045797 | AH4: B-C1 | AI4: =Grade!AP3 -> 0 | AJ4: =Kecepatan!B3*(Parameter!$D$12*Kecepatan!B3^2)+(Grade!M3*Parameter!$D$7) -> 382202.74 | AK4: =Kecepatan!C3*(Parameter!$D$12*Kecepatan!C3^2)+(Grade!R3*Parameter!$D$7) -> 538740.94 | AM4: B-C1 | AN4: =AJ4/$AJ$9 -> 0.10314592 | AO4: =AK4/$AJ$9 -> 0.14539123 | AP4: =AN4*'Fuel Ratio'!$D$3 -> 0.078061576 | AQ4: =AO4*'Fuel Ratio'!$D$3 -> 0.11003314 | AS4: B-C1 | AT4: =Grade!BA3 -> 0 | AU4: =Kecepatan!B3*(Parameter!$D$12*Kecepatan!B3^2)+(Grade!N3*Parameter!$D$7) -> 382202.74 | AV4: =Kecepatan!C3*(Parameter!$D$12*Kecepatan!C3^2)+(Grade!S3*Parameter!$D$7) -> 538740.94 | AX4: B-C1 | AY4: =AU4/$AU$9 -> 0.08599659 | AZ4: =AV4/$AU$9 -> 0.12121808 | BA4: =AY4*'Fuel Ratio'!$D$3 -> 0.065082842 | BB4: =AZ4*'Fuel Ratio'!$D$3 -> 0.091738724
A5: C1-C2 | B5: =Grade!I4 -> 0.34 | C5: =Kecepatan!B4*(Parameter!$D$12*Kecepatan!B4^2)+(Grade!J4*Parameter!$D$7) -> -826648.61 | D5: =Kecepatan!C4*(Parameter!$D$12*Kecepatan!C4^2)+(Grade!O4*Parameter!$D$8) -> 604151.86 | F5: C1-C2 | G5: =C5/$C$9 -> -0.26230592 | H5: =D5/$C$9 -> 0.19170492 | I5: =G5*'Fuel Ratio'!$D$3 -> -0.19851502 | J5: =H5*'Fuel Ratio'!$D$3 -> 0.14508367 | L5: C1-C2 | M5: 0.1 | N5: =Kecepatan!B4*(Parameter!$D$12*Kecepatan!B4^2)+(Grade!K4*Parameter!$D$7) -> -298763.72 | O5: =Kecepatan!C4*(Parameter!$D$12*Kecepatan!C4^2)+(Grade!P4*Parameter!$D$7) -> 101814.02 | Q5: C1-C2 | R5: =N5/$N$9 -> -0.08157127 | S5: =O5/$N$9 -> 0.027798216 | T5: =R5*'Fuel Ratio'!$D$3 -> -0.061733728 | U5: =S5*'Fuel Ratio'!$D$3 -> 0.021037891 | W5: C1-C2 | X5: 0.2 | Y5: =Kecepatan!B4*(Parameter!$D$12*Kecepatan!B4^2)+(Grade!L4*Parameter!$D$7) -> 578207.54 | Z5: =Kecepatan!C4*(Parameter!$D$12*Kecepatan!C4^2)+(Grade!Q4*Parameter!$D$7) -> 69553.336 | AB5: C1-C2 | AC5: =Y5/$Y$9 -> 0.12828188 | AD5: =Z5/$Y$9 -> 0.015431195 | AE5: =AC5*'Fuel Ratio'!$D$3 -> 0.097084659 | AF5: =AD5*'Fuel Ratio'!$D$3 -> 0.01167844 | AH5: C1-C2 | AI5: 0.3 | AJ5: =Kecepatan!B4*(Parameter!$D$12*Kecepatan!B4^2)+(Grade!M4*Parameter!$D$7) -> -567758.16 | AK5: =Kecepatan!C4*(Parameter!$D$12*Kecepatan!C4^2)+(Grade!R4*Parameter!$D$7) -> 413655.59 | AM5: C1-C2 | AN5: =AJ5/$AJ$9 -> -0.15322218 | AO5: =AK5/$AJ$9 -> 0.11163417 | AP5: =AN5*'Fuel Ratio'!$D$3 -> -0.11595965 | AQ5: =AO5*'Fuel Ratio'!$D$3 -> 0.084485548 | AS5: C1-C2 | AT5: 0.4 | AU5: =Kecepatan!B4*(Parameter!$D$12*Kecepatan!B4^2)+(Grade!N4*Parameter!$D$7) -> 818506.47 | AV5: =Kecepatan!C4*(Parameter!$D$12*Kecepatan!C4^2)+(Grade!S4*Parameter!$D$7) -> -233671.76 | AX5: C1-C2 | AY5: =AU5/$AU$9 -> 0.18416604 | AZ5: =AV5/$AU$9 -> -0.052576742 | BA5: =AY5*'Fuel Ratio'!$D$3 -> 0.13937819 | BB5: =AZ5*'Fuel Ratio'!$D$3 -> -0.039790459
A6: C2-D | B6: =Grade!I5 -> 0 | C6: =Kecepatan!B5*(Parameter!$D$12*Kecepatan!B5^2)+(Grade!J5*Parameter!$D$7) -> 382202.74 | D6: =Kecepatan!C5*(Parameter!$D$12*Kecepatan!C5^2)+(Grade!O5*Parameter!$D$8) -> 417342.19 | F6: C2-D | G6: =C6/$C$9 -> 0.1212777 | H6: =D6/$C$9 -> 0.13242788 | I6: =G6*'Fuel Ratio'!$D$3 -> 0.091783839 | J6: =H6*'Fuel Ratio'!$D$3 -> 0.10022238 | L6: C2-D | M6: =Grade!T5 -> 0 | N6: =Kecepatan!B5*(Parameter!$D$12*Kecepatan!B5^2)+(Grade!K5*Parameter!$D$7) -> 382202.74 | O6: =Kecepatan!C5*(Parameter!$D$12*Kecepatan!C5^2)+(Grade!P5*Parameter!$D$7) -> 538740.94 | Q6: C2-D | R6: =N6/$N$9 -> 0.10435257 | S6: =O6/$N$9 -> 0.1470921 | T6: =R6*'Fuel Ratio'!$D$3 -> 0.078974781 | U6: =S6*'Fuel Ratio'!$D$3 -> 0.11132036 | W6: C2-D | X6: =Grade!AE5 -> 0 | Y6: =Kecepatan!B5*(Parameter!$D$12*Kecepatan!B5^2)+(Grade!L5*Parameter!$D$7) -> 382202.74 | Z6: =Kecepatan!C5*(Parameter!$D$12*Kecepatan!C5^2)+(Grade!Q5*Parameter!$D$7) -> 538740.94 | AB6: C2-D | AC6: =Y6/$Y$9 -> 0.084796002 | AD6: =Z6/$Y$9 -> 0.11952577 | AE6: =AC6*'Fuel Ratio'!$D$3 -> 0.064174228 | AF6: =AD6*'Fuel Ratio'!$D$3 -> 0.09045797 | AH6: C2-D | AI6: =Grade!AP5 -> 0 | AJ6: =Kecepatan!B5*(Parameter!$D$12*Kecepatan!B5^2)+(Grade!M5*Parameter!$D$7) -> 382202.74 | AK6: =Kecepatan!C5*(Parameter!$D$12*Kecepatan!C5^2)+(Grade!R5*Parameter!$D$7) -> 538740.94 | AM6: C2-D | AN6: =AJ6/$AJ$9 -> 0.10314592 | AO6: =AK6/$AJ$9 -> 0.14539123 | AP6: =AN6*'Fuel Ratio'!$D$3 -> 0.078061576 | AQ6: =AO6*'Fuel Ratio'!$D$3 -> 0.11003314 | AS6: C2-D | AT6: =Grade!BA5 -> 0 | AU6: =Kecepatan!B5*(Parameter!$D$12*Kecepatan!B5^2)+(Grade!N5*Parameter!$D$7) -> 382202.74 | AV6: =Kecepatan!C5*(Parameter!$D$12*Kecepatan!C5^2)+(Grade!S5*Parameter!$D$7) -> 538740.94 | AX6: C2-D | AY6: =AU6/$AU$9 -> 0.08599659 | AZ6: =AV6/$AU$9 -> 0.12121808 | BA6: =AY6*'Fuel Ratio'!$D$3 -> 0.065082842 | BB6: =AZ6*'Fuel Ratio'!$D$3 -> 0.091738724
A7: D-E | B7: =Grade!I6 -> 0 | C7: =Kecepatan!B6*(Parameter!$D$12*Kecepatan!B6^2)+(Grade!J6*Parameter!$D$7) -> 451810.91 | D7: =Kecepatan!C6*(Parameter!$D$12*Kecepatan!C6^2)+(Grade!O6*Parameter!$D$8) -> 523518.71 | F7: D-E | G7: =C7/$C$9 -> 0.14336524 | H7: =D7/$C$9 -> 0.16611902 | I7: =G7*'Fuel Ratio'!$D$3 -> 0.10849985 | J7: =H7*'Fuel Ratio'!$D$3 -> 0.12572008 | L7: D-E | M7: =Grade!T6 -> 0 | N7: =Kecepatan!B6*(Parameter!$D$12*Kecepatan!B6^2)+(Grade!K6*Parameter!$D$7) -> 451810.91 | O7: =Kecepatan!C6*(Parameter!$D$12*Kecepatan!C6^2)+(Grade!P6*Parameter!$D$7) -> 644917.46 | Q7: D-E | R7: =N7/$N$9 -> 0.12335765 | S7: =O7/$N$9 -> 0.17608141 | T7: =R7*'Fuel Ratio'!$D$3 -> 0.09335796 | U7: =S7*'Fuel Ratio'!$D$3 -> 0.13325968 | W7: D-E | X7: =Grade!AE6 -> 0 | Y7: =Kecepatan!B6*(Parameter!$D$12*Kecepatan!B6^2)+(Grade!L6*Parameter!$D$7) -> 451810.91 | Z7: =Kecepatan!C6*(Parameter!$D$12*Kecepatan!C6^2)+(Grade!Q6*Parameter!$D$7) -> 644917.46 | AB7: D-E | AC7: =Y7/$Y$9 -> 0.10023936 | AD7: =Z7/$Y$9 -> 0.14308224 | AE7: =AC7*'Fuel Ratio'!$D$3 -> 0.075861876 | AF7: =AD7*'Fuel Ratio'!$D$3 -> 0.10828567 | AH7: D-E | AI7: =Grade!AP6 -> 0 | AJ7: =Kecepatan!B6*(Parameter!$D$12*Kecepatan!B6^2)+(Grade!M6*Parameter!$D$7) -> 451810.91 | AK7: =Kecepatan!C6*(Parameter!$D$12*Kecepatan!C6^2)+(Grade!R6*Parameter!$D$7) -> 644917.46 | AM7: D-E | AN7: =AJ7/$AJ$9 -> 0.12193123 | AO7: =AK7/$AJ$9 -> 0.17404533 | AP7: =AN7*'Fuel Ratio'!$D$3 -> 0.092278439 | AQ7: =AO7*'Fuel Ratio'!$D$3 -> 0.13171877 | AS7: D-E | AT7: =Grade!BA6 -> 0 | AU7: =Kecepatan!B6*(Parameter!$D$12*Kecepatan!B6^2)+(Grade!N6*Parameter!$D$7) -> 451810.91 | AV7: =Kecepatan!C6*(Parameter!$D$12*Kecepatan!C6^2)+(Grade!S6*Parameter!$D$7) -> 644917.46 | AX7: D-E | AY7: =AU7/$AU$9 -> 0.10165861 | AZ7: =AV7/$AU$9 -> 0.14510807 | BA7: =AY7*'Fuel Ratio'!$D$3 -> 0.07693597 | BB7: =AZ7*'Fuel Ratio'!$D$3 -> 0.10981884
A8: Total | C8: =SUM(C3:C7) -> 771770.51 | D8: =SUM(D3:D7) -> 2379697.1 | F8: Total | I8: =SUM(I3:I7) -> 0.18533635 | J8: =SUM(J3:J7) -> 0.57147089 | L8: Total | N8: =SUM(N3:N7) -> 1299655.4 | O8: =SUM(O3:O7) -> 2362954.3 | Q8: Total | T8: =SUM(T3:T7) -> 0.26854858 | U8: =SUM(U3:U7) -> 0.48825867 | W8: Total | Y8: =SUM(Y3:Y7) -> 2176626.7 | Z8: =SUM(Z3:Z7) -> 2330693.6 | AB8: Total | AE8: =SUM(AE3:AE7) -> 0.36546922 | AF8: =SUM(AF3:AF7) -> 0.39133802 | AH8: Total | AJ8: =SUM(AJ3:AJ7) -> 1030661 | AK8: =SUM(AK3:AK7) -> 2674795.9 | AM8: Total | AP8: =SUM(AP3:AP7) -> 0.21050351 | AQ8: =SUM(AQ3:AQ7) -> 0.54630373 | AS8: Total | AU8: =SUM(AU3:AU7) -> 2416925.6 | AV8: =SUM(AV3:AV7) -> 2027468.5 | AX8: Total | BA8: =SUM(BA3:BA7) -> 0.41156269 | BB8: =SUM(BB3:BB7) -> 0.34524455
C9: =SUM(C8:D8) -> 3151467.6 | I9: =SUM(I8:J8) -> 0.75680724 | N9: =SUM(N8:O8) -> 3662609.7 | T9: =SUM(T8:U8) -> 0.75680724 | Y9: =SUM(Y8:Z8) -> 4507320.3 | AE9: =SUM(AE8:AF8) -> 0.75680724 | AJ9: =SUM(AJ8:AK8) -> 3705456.8 | AP9: =SUM(AP8:AQ8) -> 0.75680724 | AU9: =SUM(AU8:AV8) -> 4444394.1 | BA9: =SUM(BA8:BB8) -> 0.75680724
S11: Fuel Consumption
R12: Grade | S12: Muatan | T12: Kosongan
R13: =M5 -> 0.1
R14: =X5 -> 0.2
R15: =AI5 -> 0.3
R16: =B5 -> 0.34
R17: =AT5 -> 0.4

Sheet Regresi HT420
A1: Segmen | B1: Grade | C1: P(kW) | F1: Segmen | G1: P(%) | I1: Fuel consumption | L1: Segmen | M1: Grade | N1: P(kW) | Q1: Segmen | R1: P(%) | T1: Fuel consumption | W1: Segmen | X1: Grade | Y1: P(kW) | AB1: Segmen | AC1: P(%) | AE1: Fuel consumption | AH1: Segmen | AI1: Grade | AJ1: P(kW) | AM1: Segmen | AN1: P(%) | AP1: Fuel consumption | AS1: Segmen | AT1: Grade | AU1: P(kW) | AX1: Segmen | AY1: P(%) | BA1: Fuel consumption
C2: Pa | D2: Pk | G2: Pa | H2: Pk | I2: Muatan | J2: Kosongan | N2: Pa | O2: Pk | R2: Pa | S2: Pk | T2: Muatan | U2: Kosongan | Y2: Pa | Z2: Pk | AC2: Pa | AD2: Pk | AE2: Muatan | AF2: Kosongan | AJ2: Pa | AK2: Pk | AN2: Pa | AO2: Pk | AP2: Muatan | AQ2: Kosongan | AU2: Pa | AV2: Pk | AY2: Pa | AZ2: Pk | BA2: Muatan | BB2: Kosongan
A3: A-B | B3: =Grade!I2 -> 0 | C3: =Kecepatan!B2*(Parameter!$D$12*Kecepatan!B2^2)+(Grade!J2*Parameter!$D$7) -> 382202.74 | D3: =Kecepatan!C2*(Parameter!$D$12*Kecepatan!C2^2)+(Grade!O2*Parameter!$D$8) -> 417342.19 | F3: A-B | G3: =C3/$C$9 -> 0.1212777 | H3: =D3/$C$9 -> 0.13242788 | I3: =G3*'Fuel Ratio'!$D$4 -> 0.079508822 | J3: =H3*'Fuel Ratio'!$D$4 -> 0.086818807 | L3: A-B | M3: =Grade!T2 -> 0 | N3: =Kecepatan!B2*(Parameter!$D$12*Kecepatan!B2^2)+(Grade!K2*Parameter!$D$7) -> 382202.74 | O3: =Kecepatan!C2*(Parameter!$D$12*Kecepatan!C2^2)+(Grade!P2*Parameter!$D$7) -> 538740.94 | Q3: A-B | R3: =N3/$N$9 -> 0.10435257 | S3: =O3/$N$9 -> 0.1470921 | T3: =R3*'Fuel Ratio'!$D$4 -> 0.068412826 | U3: =S3*'Fuel Ratio'!$D$4 -> 0.096432564 | W3: A-B | X3: =Grade!AE2 -> 0 | Y3: =Kecepatan!B2*(Parameter!$D$12*Kecepatan!B2^2)+(Grade!L2*Parameter!$D$7) -> 382202.74 | Z3: =Kecepatan!C2*(Parameter!$D$12*Kecepatan!C2^2)+(Grade!Q2*Parameter!$D$7) -> 538740.94 | AB3: A-B | AC3: =Y3/$Y$9 -> 0.084796002 | AD3: =Z3/$Y$9 -> 0.11952577 | AE3: =AC3*'Fuel Ratio'!$D$4 -> 0.055591674 | AF3: =AD3*'Fuel Ratio'!$D$4 -> 0.078360272 | AH3: A-B | AI3: =Grade!AP2 -> 0 | AJ3: =Kecepatan!B2*(Parameter!$D$12*Kecepatan!B2^2)+(Grade!M2*Parameter!$D$7) -> 382202.74 | AK3: =Kecepatan!C2*(Parameter!$D$12*Kecepatan!C2^2)+(Grade!R2*Parameter!$D$7) -> 538740.94 | AM3: A-B | AN3: =AJ3/$AJ$9 -> 0.10314592 | AO3: =AK3/$AJ$9 -> 0.14539123 | AP3: =AN3*'Fuel Ratio'!$D$4 -> 0.067621751 | AQ3: =AO3*'Fuel Ratio'!$D$4 -> 0.09531749 | AS3: A-B | AT3: =Grade!BA2 -> 0 | AU3: =Kecepatan!B2*(Parameter!$D$12*Kecepatan!B2^2)+(Grade!N2*Parameter!$D$7) -> 382202.74 | AV3: =Kecepatan!C2*(Parameter!$D$12*Kecepatan!C2^2)+(Grade!S2*Parameter!$D$7) -> 538740.94 | AX3: A-B | AY3: =AU3/$AU$9 -> 0.08599659 | AZ3: =AV3/$AU$9 -> 0.12121808 | BA3: =AY3*'Fuel Ratio'!$D$4 -> 0.056378771 | BB3: =AZ3*'Fuel Ratio'!$D$4 -> 0.07946974
A4: B-C1 | B4: =Grade!I3 -> 0 | C4: =Kecepatan!B3*(Parameter!$D$12*Kecepatan!B3^2)+(Grade!J3*Parameter!$D$7) -> 382202.74 | D4: =Kecepatan!C3*(Parameter!$D$12*Kecepatan!C3^2)+(Grade!O3*Parameter!$D$8) -> 417342.19 | F4: B-C1 | G4: =C4/$C$9 -> 0.1212777 | H4: =D4/$C$9 -> 0.13242788 | I4: =G4*'Fuel Ratio'!$D$4 -> 0.079508822 | J4: =H4*'Fuel Ratio'!$D$4 -> 0.086818807 | L4: B-C1 | M4: =Grade!T3 -> 0 | N4: =Kecepatan!B3*(Parameter!$D$12*Kecepatan!B3^2)+(Grade!K3*Parameter!$D$7) -> 382202.74 | O4: =Kecepatan!C3*(Parameter!$D$12*Kecepatan!C3^2)+(Grade!P3*Parameter!$D$7) -> 538740.94 | Q4: B-C1 | R4: =N4/$N$9 -> 0.10435257 | S4: =O4/$N$9 -> 0.1470921 | T4: =R4*'Fuel Ratio'!$D$4 -> 0.068412826 | U4: =S4*'Fuel Ratio'!$D$4 -> 0.096432564 | W4: B-C1 | X4: =Grade!AE3 -> 0 | Y4: =Kecepatan!B3*(Parameter!$D$12*Kecepatan!B3^2)+(Grade!L3*Parameter!$D$7) -> 382202.74 | Z4: =Kecepatan!C3*(Parameter!$D$12*Kecepatan!C3^2)+(Grade!Q3*Parameter!$D$7) -> 538740.94 | AB4: B-C1 | AC4: =Y4/$Y$9 -> 0.084796002 | AD4: =Z4/$Y$9 -> 0.11952577 | AE4: =AC4*'Fuel Ratio'!$D$4 -> 0.055591674 | AF4: =AD4*'Fuel Ratio'!$D$4 -> 0.078360272 | AH4: B-C1 | AI4: =Grade!AP3 -> 0 | AJ4: =Kecepatan!B3*(Parameter!$D$12*Kecepatan!B3^2)+(Grade!M3*Parameter!$D$7) -> 382202.74 | AK4: =Kecepatan!C3*(Parameter!$D$12*Kecepatan!C3^2)+(Grade!R3*Parameter!$D$7) -> 538740.94 | AM4: B-C1 | AN4: =AJ4/$AJ$9 -> 0.10314592 | AO4: =AK4/$AJ$9 -> 0.14539123 | AP4: =AN4*'Fuel Ratio'!$D$4 -> 0.067621751 | AQ4: =AO4*'Fuel Ratio'!$D$4 -> 0.09531749 | AS4: B-C1 | AT4: =Grade!BA3 -> 0 | AU4: =Kecepatan!B3*(Parameter!$D$12*Kecepatan!B3^2)+(Grade!N3*Parameter!$D$7) -> 382202.74 | AV4: =Kecepatan!C3*(Parameter!$D$12*Kecepatan!C3^2)+(Grade!S3*Parameter!$D$7) -> 538740.94 | AX4: B-C1 | AY4: =AU4/$AU$9 -> 0.08599659 | AZ4: =AV4/$AU$9 -> 0.12121808 | BA4: =AY4*'Fuel Ratio'!$D$4 -> 0.056378771 | BB4: =AZ4*'Fuel Ratio'!$D$4 -> 0.07946974
A5: C1-C2 | B5: =Grade!I4 -> 0.34 | C5: =Kecepatan!B4*(Parameter!$D$12*Kecepatan!B4^2)+(Grade!J4*Parameter!$D$7) -> -826648.61 | D5: =Kecepatan!C4*(Parameter!$D$12*Kecepatan!C4^2)+(Grade!O4*Parameter!$D$8) -> 604151.86 | F5: C1-C2 | G5: =C5/$C$9 -> -0.26230592 | H5: =D5/$C$9 -> 0.19170492 | I5: =G5*'Fuel Ratio'!$D$4 -> -0.17196595 | J5: =H5*'Fuel Ratio'!$D$4 -> 0.12568042 | L5: C1-C2 | M5: 0.1 | N5: =Kecepatan!B4*(Parameter!$D$12*Kecepatan!B4^2)+(Grade!K4*Parameter!$D$7) -> -298763.72 | O5: =Kecepatan!C4*(Parameter!$D$12*Kecepatan!C4^2)+(Grade!P4*Parameter!$D$7) -> 101814.02 | Q5: C1-C2 | R5: =N5/$N$9 -> -0.08157127 | S5: =O5/$N$9 -> 0.027798216 | T5: =R5*'Fuel Ratio'!$D$4 -> -0.053477562 | U5: =S5*'Fuel Ratio'!$D$4 -> 0.018224319 | W5: C1-C2 | X5: 0.2 | Y5: =Kecepatan!B4*(Parameter!$D$12*Kecepatan!B4^2)+(Grade!L4*Parameter!$D$7) -> 578207.54 | Z5: =Kecepatan!C4*(Parameter!$D$12*Kecepatan!C4^2)+(Grade!Q4*Parameter!$D$7) -> 69553.336 | AB5: C1-C2 | AC5: =Y5/$Y$9 -> 0.12828188 | AD5: =Z5/$Y$9 -> 0.015431195 | AE5: =AC5*'Fuel Ratio'!$D$4 -> 0.084100719 | AF5: =AD5*'Fuel Ratio'!$D$4 -> 0.010116585 | AH5: C1-C2 | AI5: 0.3 | AJ5: =Kecepatan!B4*(Parameter!$D$12*Kecepatan!B4^2)+(Grade!M4*Parameter!$D$7) -> -567758.16 | AK5: =Kecepatan!C4*(Parameter!$D$12*Kecepatan!C4^2)+(Grade!R4*Parameter!$D$7) -> 413655.59 | AM5: C1-C2 | AN5: =AJ5/$AJ$9 -> -0.15322218 | AO5: =AK5/$AJ$9 -> 0.11163417 | AP5: =AN5*'Fuel Ratio'!$D$4 -> -0.1004514 | AQ5: =AO5*'Fuel Ratio'!$D$4 -> 0.073186591 | AS5: C1-C2 | AT5: 0.4 | AU5: =Kecepatan!B4*(Parameter!$D$12*Kecepatan!B4^2)+(Grade!N4*Parameter!$D$7) -> 818506.47 | AV5: =Kecepatan!C4*(Parameter!$D$12*Kecepatan!C4^2)+(Grade!S4*Parameter!$D$7) -> -233671.76 | AX5: C1-C2 | AY5: =AU5/$AU$9 -> 0.18416604 | AZ5: =AV5/$AU$9 -> -0.052576742 | BA5: =AY5*'Fuel Ratio'!$D$4 -> 0.12073799 | BB5: =AZ5*'Fuel Ratio'!$D$4 -> -0.03446895
A6: C2-D | B6: =Grade!I5 -> 0 | C6: =Kecepatan!B5*(Parameter!$D$12*Kecepatan!B5^2)+(Grade!J5*Parameter!$D$7) -> 382202.74 | D6: =Kecepatan!C5*(Parameter!$D$12*Kecepatan!C5^2)+(Grade!O5*Parameter!$D$8) -> 417342.19 | F6: C2-D | G6: =C6/$C$9 -> 0.1212777 | H6: =D6/$C$9 -> 0.13242788 | I6: =G6*'Fuel Ratio'!$D$4 -> 0.079508822 | J6: =H6*'Fuel Ratio'!$D$4 -> 0.086818807 | L6: C2-D | M6: =Grade!T5 -> 0 | N6: =Kecepatan!B5*(Parameter!$D$12*Kecepatan!B5^2)+(Grade!K5*Parameter!$D$7) -> 382202.74 | O6: =Kecepatan!C5*(Parameter!$D$12*Kecepatan!C5^2)+(Grade!P5*Parameter!$D$7) -> 538740.94 | Q6: C2-D | R6: =N6/$N$9 -> 0.10435257 | S6: =O6/$N$9 -> 0.1470921 | T6: =R6*'Fuel Ratio'!$D$4 -> 0.068412826 | U6: =S6*'Fuel Ratio'!$D$4 -> 0.096432564 | W6: C2-D | X6: =Grade!AE5 -> 0 | Y6: =Kecepatan!B5*(Parameter!$D$12*Kecepatan!B5^2)+(Grade!L5*Parameter!$D$7) -> 382202.74 | Z6: =Kecepatan!C5*(Parameter!$D$12*Kecepatan!C5^2)+(Grade!Q5*Parameter!$D$7) -> 538740.94 | AB6: C2-D | AC6: =Y6/$Y$9 -> 0.084796002 | AD6: =Z6/$Y$9 -> 0.11952577 | AE6: =AC6*'Fuel Ratio'!$D$4 -> 0.055591674 | AF6: =AD6*'Fuel Ratio'!$D$4 -> 0.078360272 | AH6: C2-D | AI6: =Grade!AP5 -> 0 | AJ6: =Kecepatan!B5*(Parameter!$D$12*Kecepatan!B5^2)+(Grade!M5*Parameter!$D$7) -> 382202.74 | AK6: =Kecepatan!C5*(Parameter!$D$12*Kecepatan!C5^2)+(Grade!R5*Parameter!$D$7) -> 538740.94 | AM6: C2-D | AN6: =AJ6/$AJ$9 -> 0.10314592 | AO6: =AK6/$AJ$9 -> 0.14539123 | AP6: =AN6*'Fuel Ratio'!$D$4 -> 0.067621751 | AQ6: =AO6*'Fuel Ratio'!$D$4 -> 0.09531749 | AS6: C2-D | AT6: =Grade!BA5 -> 0 | AU6: =Kecepatan!B5*(Parameter!$D$12*Kecepatan!B5^2)+(Grade!N5*Parameter!$D$7) -> 382202.74 | AV6: =Kecepatan!C5*(Parameter!$D$12*Kecepatan!C5^2)+(Grade!S5*Parameter!$D$7) -> 538740.94 | AX6: C2-D | AY6: =AU6/$AU$9 -> 0.08599659 | AZ6: =AV6/$AU$9 -> 0.12121808 | BA6: =AY6*'Fuel Ratio'!$D$4 -> 0.056378771 | BB6: =AZ6*'Fuel Ratio'!$D$4 -> 0.07946974
A7: D-E | B7: =Grade!I6 -> 0 | C7: =Kecepatan!B6*(Parameter!$D$12*Kecepatan!B6^2)+(Grade!J6*Parameter!$D$7) -> 451810.91 | D7: =Kecepatan!C6*(Parameter!$D$12*Kecepatan!C6^2)+(Grade!O6*Parameter!$D$8) -> 523518.71 | F7: D-E | G7: =C7/$C$9 -> 0.14336524 | H7: =D7/$C$9 -> 0.16611902 | I7: =G7*'Fuel Ratio'!$D$4 -> 0.093989262 | J7: =H7*'Fuel Ratio'!$D$4 -> 0.10890648 | L7: D-E | M7: =Grade!T6 -> 0 | N7: =Kecepatan!B6*(Parameter!$D$12*Kecepatan!B6^2)+(Grade!K6*Parameter!$D$7) -> 451810.91 | O7: =Kecepatan!C6*(Parameter!$D$12*Kecepatan!C6^2)+(Grade!P6*Parameter!$D$7) -> 644917.46 | Q7: D-E | R7: =N7/$N$9 -> 0.12335765 | S7: =O7/$N$9 -> 0.17608141 | T7: =R7*'Fuel Ratio'!$D$4 -> 0.080872422 | U7: =S7*'Fuel Ratio'!$D$4 -> 0.11543776 | W7: D-E | X7: =Grade!AE6 -> 0 | Y7: =Kecepatan!B6*(Parameter!$D$12*Kecepatan!B6^2)+(Grade!L6*Parameter!$D$7) -> 451810.91 | Z7: =Kecepatan!C6*(Parameter!$D$12*Kecepatan!C6^2)+(Grade!Q6*Parameter!$D$7) -> 644917.46 | AB7: D-E | AC7: =Y7/$Y$9 -> 0.10023936 | AD7: =Z7/$Y$9 -> 0.14308224 | AE7: =AC7*'Fuel Ratio'!$D$4 -> 0.065716235 | AF7: =AD7*'Fuel Ratio'!$D$4 -> 0.093803727 | AH7: D-E | AI7: =Grade!AP6 -> 0 | AJ7: =Kecepatan!B6*(Parameter!$D$12*Kecepatan!B6^2)+(Grade!M6*Parameter!$D$7) -> 451810.91 | AK7: =Kecepatan!C6*(Parameter!$D$12*Kecepatan!C6^2)+(Grade!R6*Parameter!$D$7) -> 644917.46 | AM7: D-E | AN7: =AJ7/$AJ$9 -> 0.12193123 | AO7: =AK7/$AJ$9 -> 0.17404533 | AP7: =AN7*'Fuel Ratio'!$D$4 -> 0.079937274 | AQ7: =AO7*'Fuel Ratio'!$D$4 -> 0.11410292 | AS7: D-E | AT7: =Grade!BA6 -> 0 | AU7: =Kecepatan!B6*(Parameter!$D$12*Kecepatan!B6^2)+(Grade!N6*Parameter!$D$7) -> 451810.91 | AV7: =Kecepatan!C6*(Parameter!$D$12*Kecepatan!C6^2)+(Grade!S6*Parameter!$D$7) -> 644917.46 | AX7: D-E | AY7: =AU7/$AU$9 -> 0.10165861 | AZ7: =AV7/$AU$9 -> 0.14510807 | BA7: =AY7*'Fuel Ratio'!$D$4 -> 0.066646681 | BB7: =AZ7*'Fuel Ratio'!$D$4 -> 0.095131852
A8: Total | C8: =SUM(C3:C7) -> 771770.51 | D8: =SUM(D3:D7) -> 2379697.1 | F8: Total | I8: =SUM(I3:I7) -> 0.16054978 | J8: =SUM(J3:J7) -> 0.49504333 | L8: Total | N8: =SUM(N3:N7) -> 1299655.4 | O8: =SUM(O3:O7) -> 2362954.3 | Q8: Total | T8: =SUM(T3:T7) -> 0.23263334 | U8: =SUM(U3:U7) -> 0.42295977 | W8: Total | Y8: =SUM(Y3:Y7) -> 2176626.7 | Z8: =SUM(Z3:Z7) -> 2330693.6 | AB8: Total | AE8: =SUM(AE3:AE7) -> 0.31659198 | AF8: =SUM(AF3:AF7) -> 0.33900113 | AH8: Total | AJ8: =SUM(AJ3:AJ7) -> 1030661 | AK8: =SUM(AK3:AK7) -> 2674795.9 | AM8: Total | AP8: =SUM(AP3:AP7) -> 0.18235112 | AQ8: =SUM(AQ3:AQ7) -> 0.47324198 | AS8: Total | AU8: =SUM(AU3:AU7) -> 2416925.6 | AV8: =SUM(AV3:AV7) -> 2027468.5 | AX8: Total | BA8: =SUM(BA3:BA7) -> 0.35652098 | BB8: =SUM(BB3:BB7) -> 0.29907212
C9: =SUM(C8:D8) -> 3151467.6 | I9: =SUM(I8:J8) -> 0.6555931 | N9: =SUM(N8:O8) -> 3662609.7 | T9: =SUM(T8:U8) -> 0.6555931 | Y9: =SUM(Y8:Z8) -> 4507320.3 | AE9: =SUM(AE8:AF8) -> 0.6555931 | AJ9: =SUM(AJ8:AK8) -> 3705456.8 | AP9: =SUM(AP8:AQ8) -> 0.6555931 | AU9: =SUM(AU8:AV8) -> 4444394.1 | BA9: =SUM(BA8:BB8) -> 0.6555931

Sheet Regresi HT421
A1: Segmen | B1: Grade | C1: P(kW) | F1: Segmen | G1: P(%) | I1: Fuel consumption | L1: Segmen | M1: Grade | N1: P(kW) | Q1: Segmen | R1: P(%) | T1: Fuel consumption | W1: Segmen | X1: Grade | Y1: P(kW) | AB1: Segmen | AC1: P(%) | AE1: Fuel consumption | AH1: Segmen | AI1: Grade | AJ1: P(kW) | AM1: Segmen | AN1: P(%) | AP1: Fuel consumption | AS1: Segmen | AT1: Grade | AU1: P(kW) | AX1: Segmen | AY1: P(%) | BA1: Fuel consumption
C2: Pa | D2: Pk | G2: Pa | H2: Pk | I2: Muatan | J2: Kosongan | N2: Pa | O2: Pk | R2: Pa | S2: Pk | T2: Muatan | U2: Kosongan | Y2: Pa | Z2: Pk | AC2: Pa | AD2: Pk | AE2: Muatan | AF2: Kosongan | AJ2: Pa | AK2: Pk | AN2: Pa | AO2: Pk | AP2: Muatan | AQ2: Kosongan | AU2: Pa | AV2: Pk | AY2: Pa | AZ2: Pk | BA2: Muatan | BB2: Kosongan
A3: A-B | B3: =Grade!I2 -> 0 | C3: =Kecepatan!B2*(Parameter!$D$12*Kecepatan!B2^2)+(Grade!J2*Parameter!$D$7) -> 382202.74 | D3: =Kecepatan!C2*(Parameter!$D$12*Kecepatan!C2^2)+(Grade!O2*Parameter!$D$8) -> 417342.19 | F3: A-B | G3: =C3/$C$9 -> 0.1212777 | H3: =D3/$C$9 -> 0.13242788 | I3: =G3*'Fuel Ratio'!$D$5 -> 0.088408604 | J3: =H3*'Fuel Ratio'!$D$5 -> 0.096536829 | L3: A-B | M3: =Grade!T2 -> 0 | N3: =Kecepatan!B2*(Parameter!$D$12*Kecepatan!B2^2)+(Grade!K2*Parameter!$D$7) -> 382202.74 | O3: =Kecepatan!C2*(Parameter!$D$12*Kecepatan!C2^2)+(Grade!P2*Parameter!$D$7) -> 538740.94 | Q3: A-B | R3: =N3/$N$9 -> 0.10435257 | S3: =O3/$N$9 -> 0.1470921 | T3: =R3*'Fuel Ratio'!$D$5 -> 0.076070584 | U3: =S3*'Fuel Ratio'!$D$5 -> 0.1072267 | W3: A-B | X3: =Grade!AE2 -> 0 | Y3: =Kecepatan!B2*(Parameter!$D$12*Kecepatan!B2^2)+(Grade!L2*Parameter!$D$7) -> 382202.74 | Z3: =Kecepatan!C2*(Parameter!$D$12*Kecepatan!C2^2)+(Grade!Q2*Parameter!$D$7) -> 538740.94 | AB3: A-B | AC3: =Y3/$Y$9 -> 0.084796002 | AD3: =Z3/$Y$9 -> 0.11952577 | AE3: =AC3*'Fuel Ratio'!$D$5 -> 0.061814302 | AF3: =AD3*'Fuel Ratio'!$D$5 -> 0.087131493 | AH3: A-B | AI3: =Grade!AP2 -> 0 | AJ3: =Kecepatan!B2*(Parameter!$D$12*Kecepatan!B2^2)+(Grade!M2*Parameter!$D$7) -> 382202.74 | AK3: =Kecepatan!C2*(Parameter!$D$12*Kecepatan!C2^2)+(Grade!R2*Parameter!$D$7) -> 538740.94 | AM3: A-B | AN3: =AJ3/$AJ$9 -> 0.10314592 | AO3: =AK3/$AJ$9 -> 0.14539123 | AP3: =AN3*'Fuel Ratio'!$D$5 -> 0.07519096 | AQ3: =AO3*'Fuel Ratio'!$D$5 -> 0.10598681 | AS3: A-B | AT3: =Grade!BA2 -> 0 | AU3: =Kecepatan!B2*(Parameter!$D$12*Kecepatan!B2^2)+(Grade!N2*Parameter!$D$7) -> 382202.74 | AV3: =Kecepatan!C2*(Parameter!$D$12*Kecepatan!C2^2)+(Grade!S2*Parameter!$D$7) -> 538740.94 | AX3: A-B | AY3: =AU3/$AU$9 -> 0.08599659 | AZ3: =AV3/$AU$9 -> 0.12121808 | BA3: =AY3*'Fuel Ratio'!$D$5 -> 0.062689503 | BB3: =AZ3*'Fuel Ratio'!$D$5 -> 0.088365148
